Workbook
Name Categories: OFFSET('[1]Admin & Settings'!$C$10,1,,COUNTA('[1]Admin & Settings'!$C$10:$C$33)-1,1)
Name Categories: OFFSET('[1]Admin & Settings'!$C$10,1,,COUNTA('[1]Admin & Settings'!$C$10:$C$33)-1,1)
Name Categories: OFFSET('[1]Admin & Settings'!$C$10,1,,COUNTA('[1]Admin & Settings'!$C$10:$C$33)-1,1)
Name Categories: OFFSET('[1]Admin & Settings'!$C$10,1,,COUNTA('[1]Admin & Settings'!$C$10:$C$33)-1,1)
Name Categories: OFFSET('[1]Admin & Settings'!$C$10,1,,COUNTA('[1]Admin & Settings'!$C$10:$C$33)-1,1)
Name Categories: OFFSET('[1]Admin & Settings'!$C$10,1,,COUNTA('[1]Admin & Settings'!$C$10:$C$33)-1,1)
Name Categories: OFFSET('[1]Admin & Settings'!$C$10,1,,COUNTA('[1]Admin & Settings'!$C$10:$C$33)-1,1)
Name Categories: OFFSET('[1]Admin & Settings'!$C$10,1,,COUNTA('[1]Admin & Settings'!$C$10:$C$33)-1,1)
Name Categories: OFFSET('[1]Admin & Settings'!$C$10,1,,COUNTA('[1]Admin & Settings'!$C$10:$C$33)-1,1)
Name Categories: OFFSET('[1]Admin & Settings'!$C$10,1,,COUNTA('[1]Admin & Settings'!$C$10:$C$33)-1,1)
Name Categories: OFFSET('[1]Admin & Settings'!$C$10,1,,COUNTA('[1]Admin & Settings'!$C$10:$C$33)-1,1)
Name Categories: OFFSET('[1]Admin & Settings'!$C$10,1,,COUNTA('[1]Admin & Settings'!$C$10:$C$33)-1,1)
Name Categories: OFFSET('[1]Admin & Settings'!$C$10,1,,COUNTA('[1]Admin & Settings'!$C$10:$C$33)-1,1)
Name Categories: OFFSET('[1]Admin & Settings'!$C$10,1,,COUNTA('[1]Admin & Settings'!$C$10:$C$33)-1,1)
Name Categories: OFFSET('[1]Admin & Settings'!$C$10,1,,COUNTA('[1]Admin & Settings'!$C$10:$C$33)-1,1)
Name Categories: OFFSET('[2]Admin & Settings'!$C$10,1,,COUNTA('[2]Admin & Settings'!$C$10:$C$33)-1,1)
Name Months: [3]Expenses!#REF!
Name Status: [4]TE!$AB$4:$AB$6
Name Status: [4]TE!$AB$4:$AB$6
Name Status: [4]TE!$AB$4:$AB$6
Name Status: [4]TE!$AB$4:$AB$6
Name Status: [5]TE!$AB$4:$AB$6
Name Status: [4]TE!$AB$4:$AB$6
Name Status: [4]TE!$AB$4:$AB$6
Name Status: [4]TE!$AB$4:$AB$6
Name Status: [4]TE!$AB$4:$AB$6
Name Status: [4]TE!$AB$4:$AB$6
Name Status: [4]TE!$AB$4:$AB$6
Name Status: [4]TE!$AB$4:$AB$6
Name Status: [6]TE!$AB$4:$AB$6
Name Status: [4]TE!$AB$4:$AB$6
Name Status: [4]TE!$AB$4:$AB$6
Name Status: [4]TE!$AB$4:$AB$6
Name Status: [5]TE!$AB$4:$AB$6
Name Status: [4]TE!$AB$4:$AB$6
Name Status: #REF!
Name valHighlight: IFERROR(IF(AM!#REF!="Yes", TRUE, FALSE),FALSE)
Name valHighlight: IFERROR(IF(AN!#REF!="Yes", TRUE, FALSE),FALSE)
Name valHighlight: IFERROR(IF(CA!#REF!="Yes", TRUE, FALSE),FALSE)
Name valHighlight: IFERROR(IF(CP!#REF!="Yes", TRUE, FALSE),FALSE)
Name valHighlight: IFERROR(IF(DH!#REF!="Yes", TRUE, FALSE),FALSE)
Name valHighlight: IFERROR(IF(EM!#REF!="Yes", TRUE, FALSE),FALSE)
Name valHighlight: IFERROR(IF(ET!#REF!="Yes", TRUE, FALSE),FALSE)
Name valHighlight: IFERROR(IF(FR!#REF!="Yes", TRUE, FALSE),FALSE)
Name valHighlight: IFERROR(IF(GE!#REF!="Yes", TRUE, FALSE),FALSE)
Name valHighlight: IFERROR(IF(GS!#REF!="Yes", TRUE, FALSE),FALSE)
Name valHighlight: IFERROR(IF(JM!#REF!="Yes", TRUE, FALSE),FALSE)
Name valHighlight: IFERROR(IF(ML!#REF!="Yes", TRUE, FALSE),FALSE)
Name valHighlight: IFERROR(IF('RF '!#REF!="Yes", TRUE, FALSE),FALSE)
Name valHighlight: IFERROR(IF(SU!#REF!="Yes", TRUE, FALSE),FALSE)
Name valHighlight: IFERROR(IF(TE!#REF!="Yes", TRUE, FALSE),FALSE)
Name valHighlight: IFERROR(IF(#REF!="Yes", TRUE, FALSE),FALSE)

Sheet -Log
A1: 326 | B1: v022226 | C1: PAYLOG | D1: DESCRIPTION | E1: AMOUNT MXN | F1: TRK# | G1: DATE | H1: MXN
A2: 1 USD = 18 MXN | B2: 18 | C2: TYPE | D2: RENT | E2: 12000 | F2: TRK1
A3: VENDOR | B3: ACQ | C3: ACQUISITION | D3: HOUSE RENT | E3: 3500 | F3: TRK2
A4: JM (Jose Meza) | B4: =JM!M1 -> 0 | C4: EXPENSE | D4: RENT TAXES | E4: 2300 | F4: TRK3
A5: EM (Emmanuel) | B5: =EM!M1 -> 0 | C5: PRODUCTION | D5: ELECTRIC BILL AVG | E5: 500 | F5: TRK4
A6: CA (Carlos Arenas) | B6: =CA!M1 -> 40600 | C6: SUPPLIES | D6: INTERNET | E6: 500
A7: AN (Angel Cabrera) | B7: =AN!M1 -> 27000 | C7: CRATES | D7: ACCOUNTANT FEE | E7: 2300
A8: SU (Susana) | B8: =SU!M1 -> 0 | D8: ISR TAX AVG | E8: 300
A9: TE (Tellez Taller) | B9: =TE!M1 -> 0 | D9: BANK FEES | E9: 1600
A10: DH (Delfino Hernandez) | B10: =DH!M1 -> 0 | D10: BOA MONTLY TOTAL | E10: =SUM(E2:E3) -> 15500
A11: ML (Maria Luisa) | D11: BBVA MONTLY RAMSES | E11: =SUM(E4:E8) -> 5900
A12: GE (Gerardo De Gante) | D12: BBVA MONTLY MARTHA | E12: =E9 -> 1600
A13: FR (Fountain Rock) | D13: TOTAL | E13: =SUM(E2:E9) -> 23000
A14: ET (Eduardo Tellez)
A15: AM (Alejandro Meza)
A16: BT (Bernardo)
A17: RF (Roberto Florita)
A18: GS (Gift Store)
A19: CP (Cantera Puebla)

Sheet -Production
A1: ORDERS
A2: Date | B2: Vendor | C2: Description | D2: PRICE | E2: QTY | F2: TOTAL MXN | G2: ADVANCE MXN | H2: Ready Date | I2: TAGID
A3: 46065 | B3: AN (Angel Cabrera) | C3: 7" S FOUNTAIN | D3: 27000 | E3: 1 | F3: =IF(Table2[[#This Row],[QTY]]>0.1,D3*E3, " ") -> 27000 | G3: 13500
A4: 46065 | B4: CA (Carlos Arenas) | C4: BARREL CACTUS 3 PCS SET | D4: 13000 | E4: 3 | F4: =IF(Table2[[#This Row],[QTY]]>0.1,D4*E4, " ") -> 39000 | G4: 20000
F5: =IF(Table2[[#This Row],[QTY]]>0.1,D5*E5, " ")
F6: =IF(Table2[[#This Row],[QTY]]>0.1,D6*E6, " ")
F7: =IF(Table2[[#This Row],[QTY]]>0.1,D7*E7, " ")
F8: =IF(Table2[[#This Row],[QTY]]>0.1,D8*E8, " ")
F9: =IF(Table2[[#This Row],[QTY]]>0.1,D9*E9, " ")
F10: =IF(Table2[[#This Row],[QTY]]>0.1,D10*E10, " ")
F11: =IF(Table2[[#This Row],[QTY]]>0.1,D11*E11, " ")
F12: =IF(Table2[[#This Row],[QTY]]>0.1,D12*E12, " ")
F13: =IF(Table2[[#This Row],[QTY]]>0.1,D13*E13, " ")
F14: =IF(Table2[[#This Row],[QTY]]>0.1,D14*E14, " ")
F15: =IF(Table2[[#This Row],[QTY]]>0.1,D15*E15, " ")
F16: =IF(Table2[[#This Row],[QTY]]>0.1,D16*E16, " ")
... F31: =IF(Table2[[#This Row],[QTY]]>0.1,D31*E31, " ")

Sheet -Supplies
A1: SUPPLIES & LABOR | G1: REMAINING BALANCE | I1: =I2-G2 -> 0
F2: TOTAL OUT | G2: =SUM(Table115[TOTAL $]) -> 0 | H2: TOTAL IN | I2: =SUM(Table115[[#All],[$MSN IN]]) -> 0
A3: Date | B3: ITEM | C3: DESCTIPTION | D3: Q | E3: $MSN IN | F3: $MXN OUT | G3: TOTAL $ | H3: $USD | I3: TOTAL USD
G4: =IF(Table115[[#This Row],[Q]]<0.1, " ",Table115[[#This Row],[Q]]*Table115[[#This Row],[$MXN OUT]]) | H4: =IF(Table115[[#This Row],[Q]]>0.1, Table115[[#This Row],[$MSN IN]]/18, " ") | I4: =IF(Table115[[#This Row],[Q]]>0.1, Table115[[#This Row],[$USD]]*Table115[[#This Row],[Q]], " ")
G5: =IF(Table115[[#This Row],[Q]]<0.1, " ",Table115[[#This Row],[Q]]*Table115[[#This Row],[$MXN OUT]]) | H5: =IF(Table115[[#This Row],[Q]]>0.1, Table115[[#This Row],[$MSN IN]]/18, " ") | I5: =IF(Table115[[#This Row],[Q]]>0.1, Table115[[#This Row],[$USD]]*Table115[[#This Row],[Q]], " ")
G6: =IF(Table115[[#This Row],[Q]]<0.1, " ",Table115[[#This Row],[Q]]*Table115[[#This Row],[$MXN OUT]]) | H6: =IF(Table115[[#This Row],[Q]]>0.1, Table115[[#This Row],[$MSN IN]]/18, " ") | I6: =IF(Table115[[#This Row],[Q]]>0.1, Table115[[#This Row],[$USD]]*Table115[[#This Row],[Q]], " ")
G7: =IF(Table115[[#This Row],[Q]]<0.1, " ",Table115[[#This Row],[Q]]*Table115[[#This Row],[$MXN OUT]]) | H7: =IF(Table115[[#This Row],[Q]]>0.1, Table115[[#This Row],[$MSN IN]]/18, " ") | I7: =IF(Table115[[#This Row],[Q]]>0.1, Table115[[#This Row],[$USD]]*Table115[[#This Row],[Q]], " ")
G8: =IF(Table115[[#This Row],[Q]]<0.1, " ",Table115[[#This Row],[Q]]*Table115[[#This Row],[$MXN OUT]]) | H8: =IF(Table115[[#This Row],[Q]]>0.1, Table115[[#This Row],[$MSN IN]]/18, " ") | I8: =IF(Table115[[#This Row],[Q]]>0.1, Table115[[#This Row],[$USD]]*Table115[[#This Row],[Q]], " ")
G9: =IF(Table115[[#This Row],[Q]]<0.1, " ",Table115[[#This Row],[Q]]*Table115[[#This Row],[$MXN OUT]]) | H9: =IF(Table115[[#This Row],[Q]]>0.1, Table115[[#This Row],[$MSN IN]]/18, " ") | I9: =IF(Table115[[#This Row],[Q]]>0.1, Table115[[#This Row],[$USD]]*Table115[[#This Row],[Q]], " ")
G10: =IF(Table115[[#This Row],[Q]]<0.1, " ",Table115[[#This Row],[Q]]*Table115[[#This Row],[$MXN OUT]]) | H10: =IF(Table115[[#This Row],[Q]]>0.1, Table115[[#This Row],[$MSN IN]]/18, " ") | I10: =IF(Table115[[#This Row],[Q]]>0.1, Table115[[#This Row],[$USD]]*Table115[[#This Row],[Q]], " ")
G11: =IF(Table115[[#This Row],[Q]]<0.1, " ",Table115[[#This Row],[Q]]*Table115[[#This Row],[$MXN OUT]]) | H11: =IF(Table115[[#This Row],[Q]]>0.1, Table115[[#This Row],[$MSN IN]]/18, " ") | I11: =IF(Table115[[#This Row],[Q]]>0.1, Table115[[#This Row],[$USD]]*Table115[[#This Row],[Q]], " ")
G12: =IF(Table115[[#This Row],[Q]]<0.1, " ",Table115[[#This Row],[Q]]*Table115[[#This Row],[$MXN OUT]]) | H12: =IF(Table115[[#This Row],[Q]]>0.1, Table115[[#This Row],[$MSN IN]]/18, " ") | I12: =IF(Table115[[#This Row],[Q]]>0.1, Table115[[#This Row],[$USD]]*Table115[[#This Row],[Q]], " ")
G13: =IF(Table115[[#This Row],[Q]]<0.1, " ",Table115[[#This Row],[Q]]*Table115[[#This Row],[$MXN OUT]]) | H13: =IF(Table115[[#This Row],[Q]]>0.1, Table115[[#This Row],[$MSN IN]]/18, " ") | I13: =IF(Table115[[#This Row],[Q]]>0.1, Table115[[#This Row],[$USD]]*Table115[[#This Row],[Q]], " ")
G14: =IF(Table115[[#This Row],[Q]]<0.1, " ",Table115[[#This Row],[Q]]*Table115[[#This Row],[$MXN OUT]]) | H14: =IF(Table115[[#This Row],[Q]]>0.1, Table115[[#This Row],[$MSN IN]]/18, " ") | I14: =IF(Table115[[#This Row],[Q]]>0.1, Table115[[#This Row],[$USD]]*Table115[[#This Row],[Q]], " ")
G15: =IF(Table115[[#This Row],[Q]]<0.1, " ",Table115[[#This Row],[Q]]*Table115[[#This Row],[$MXN OUT]]) | H15: =IF(Table115[[#This Row],[Q]]>0.1, Table115[[#This Row],[$MSN IN]]/18, " ") | I15: =IF(Table115[[#This Row],[Q]]>0.1, Table115[[#This Row],[$USD]]*Table115[[#This Row],[Q]], " ")
... G20: =IF(Table115[[#This Row],[Q]]<0.1, " ",Table115[[#This Row],[Q]]*Table115[[#This Row],[$MXN OUT]]) | H20: =IF(Table115[[#This Row],[Q]]>0.1, Table115[[#This Row],[$MSN IN]]/18, " ") | I20: =IF(Table115[[#This Row],[Q]]>0.1, Table115[[#This Row],[$USD]]*Table115[[#This Row],[Q]], " ")

Sheet -Crates
A1: PALLETS & CRATES | P1: OWED TO SIMONA | R1: =R2-P2 -> 0
A2: SIMONA | O2: TBP | P2: =SUM(Table11524[TOTAL $]) -> 0 | Q2: PAID | R2: =SUM(Table11524[[#All],[$MSN IN]]) -> 0
A3: Date | B3: VENDOR | C3: ITEM | D3: DESCTIPTION | E3: Q | F3: KG | G3: L CM | H3: W CM | I3: D CM | J3: $MSN IN | K3: $MXN OUT | L3: TOTAL $ | M3: POUNDS | N3: H " | O3: W" | P3: D" | Q3: $USD | R3: TOTAL USD
L4: =IF(Table11524[[#This Row],[Q]]>0.1, Table11524[[#This Row],[Q]]*Table11524[[#This Row],[$MXN OUT]], " ") | M4: =IF(Table11524[[#This Row],[Q]]>0.1,F4*2.20462, " ") | N4: =IF(Table11524[[#This Row],[Q]]>0.1,G4/2.54, " ") | O4: =IF(Table11524[[#This Row],[Q]]>0.1, H4/2.54, " ") | P4: =IF(Table11524[[#This Row],[Q]]>0.1,I4/2.54, " ") | Q4: =IF(E4>0.1,K4/18," ") | R4: =IF(E4>0.1,Q4*E4," ")
L5: =IF(Table11524[[#This Row],[Q]]>0.1, Table11524[[#This Row],[Q]]*Table11524[[#This Row],[$MXN OUT]], " ") | M5: =IF(Table11524[[#This Row],[Q]]>0.1,F5*2.20462, " ") | N5: =IF(Table11524[[#This Row],[Q]]>0.1,G5/2.54, " ") | O5: =IF(Table11524[[#This Row],[Q]]>0.1, H5/2.54, " ") | P5: =IF(Table11524[[#This Row],[Q]]>0.1,I5/2.54, " ")
L6: =IF(Table11524[[#This Row],[Q]]>0.1, Table11524[[#This Row],[Q]]*Table11524[[#This Row],[$MXN OUT]], " ") | M6: =IF(Table11524[[#This Row],[Q]]>0.1,F6*2.20462, " ") | N6: =IF(Table11524[[#This Row],[Q]]>0.1,G6/2.54, " ") | O6: =IF(Table11524[[#This Row],[Q]]>0.1, H6/2.54, " ") | P6: =IF(Table11524[[#This Row],[Q]]>0.1,I6/2.54, " ")
L7: =IF(Table11524[[#This Row],[Q]]>0.1, Table11524[[#This Row],[Q]]*Table11524[[#This Row],[$MXN OUT]], " ") | M7: =IF(Table11524[[#This Row],[Q]]>0.1,F7*2.20462, " ") | N7: =IF(Table11524[[#This Row],[Q]]>0.1,G7/2.54, " ") | O7: =IF(Table11524[[#This Row],[Q]]>0.1, H7/2.54, " ") | P7: =IF(Table11524[[#This Row],[Q]]>0.1,I7/2.54, " ")
L8: =IF(Table11524[[#This Row],[Q]]>0.1, Table11524[[#This Row],[Q]]*Table11524[[#This Row],[$MXN OUT]], " ") | M8: =IF(Table11524[[#This Row],[Q]]>0.1,F8*2.20462, " ") | N8: =IF(Table11524[[#This Row],[Q]]>0.1,G8/2.54, " ") | O8: =IF(Table11524[[#This Row],[Q]]>0.1, H8/2.54, " ") | P8: =IF(Table11524[[#This Row],[Q]]>0.1,I8/2.54, " ")
L9: =IF(Table11524[[#This Row],[Q]]>0.1, Table11524[[#This Row],[Q]]*Table11524[[#This Row],[$MXN OUT]], " ") | M9: =IF(Table11524[[#This Row],[Q]]>0.1,F9*2.20462, " ") | N9: =IF(Table11524[[#This Row],[Q]]>0.1,G9/2.54, " ") | O9: =IF(Table11524[[#This Row],[Q]]>0.1, H9/2.54, " ") | P9: =IF(Table11524[[#This Row],[Q]]>0.1,I9/2.54, " ")
L10: =IF(Table11524[[#This Row],[Q]]>0.1, Table11524[[#This Row],[Q]]*Table11524[[#This Row],[$MXN OUT]], " ") | M10: =IF(Table11524[[#This Row],[Q]]>0.1,F10*2.20462, " ") | N10: =IF(Table11524[[#This Row],[Q]]>0.1,G10/2.54, " ") | O10: =IF(Table11524[[#This Row],[Q]]>0.1, H10/2.54, " ") | P10: =IF(Table11524[[#This Row],[Q]]>0.1,I10/2.54, " ")
L11: =IF(Table11524[[#This Row],[Q]]>0.1, Table11524[[#This Row],[Q]]*Table11524[[#This Row],[$MXN OUT]], " ") | M11: =IF(Table11524[[#This Row],[Q]]>0.1,F11*2.20462, " ") | N11: =IF(Table11524[[#This Row],[Q]]>0.1,G11/2.54, " ") | O11: =IF(Table11524[[#This Row],[Q]]>0.1, H11/2.54, " ") | P11: =IF(Table11524[[#This Row],[Q]]>0.1,I11/2.54, " ")
L12: =IF(Table11524[[#This Row],[Q]]>0.1, Table11524[[#This Row],[Q]]*Table11524[[#This Row],[$MXN OUT]], " ") | M12: =IF(Table11524[[#This Row],[Q]]>0.1,F12*2.20462, " ") | N12: =IF(Table11524[[#This Row],[Q]]>0.1,G12/2.54, " ") | O12: =IF(Table11524[[#This Row],[Q]]>0.1, H12/2.54, " ") | P12: =IF(Table11524[[#This Row],[Q]]>0.1,I12/2.54, " ")
L13: =IF(Table11524[[#This Row],[Q]]>0.1, Table11524[[#This Row],[Q]]*Table11524[[#This Row],[$MXN OUT]], " ") | M13: =IF(Table11524[[#This Row],[Q]]>0.1,F13*2.20462, " ") | N13: =IF(Table11524[[#This Row],[Q]]>0.1,G13/2.54, " ") | O13: =IF(Table11524[[#This Row],[Q]]>0.1, H13/2.54, " ") | P13: =IF(Table11524[[#This Row],[Q]]>0.1,I13/2.54, " ")
L14: =IF(Table11524[[#This Row],[Q]]>0.1, Table11524[[#This Row],[Q]]*Table11524[[#This Row],[$MXN OUT]], " ") | M14: =IF(Table11524[[#This Row],[Q]]>0.1,F14*2.20462, " ") | N14: =IF(Table11524[[#This Row],[Q]]>0.1,G14/2.54, " ") | O14: =IF(Table11524[[#This Row],[Q]]>0.1, H14/2.54, " ") | P14: =IF(Table11524[[#This Row],[Q]]>0.1,I14/2.54, " ")
L15: =IF(Table11524[[#This Row],[Q]]>0.1, Table11524[[#This Row],[Q]]*Table11524[[#This Row],[$MXN OUT]], " ") | M15: =IF(Table11524[[#This Row],[Q]]>0.1,F15*2.20462, " ") | N15: =IF(Table11524[[#This Row],[Q]]>0.1,G15/2.54, " ") | O15: =IF(Table11524[[#This Row],[Q]]>0.1, H15/2.54, " ") | P15: =IF(Table11524[[#This Row],[Q]]>0.1,I15/2.54, " ") | Q15: =IF(E15>0.1,K15/18," ") | R15: =IF(E15>0.1,Q15*E15," ")
L16: =IF(Table11524[[#This Row],[Q]]>0.1, Table11524[[#This Row],[Q]]*Table11524[[#This Row],[$MXN OUT]], " ") | M16: =IF(Table11524[[#This Row],[Q]]>0.1,F16*2.20462, " ") | N16: =IF(Table11524[[#This Row],[Q]]>0.1,G16/2.54, " ") | O16: =IF(Table11524[[#This Row],[Q]]>0.1, H16/2.54, " ") | P16: =IF(Table11524[[#This Row],[Q]]>0.1,I16/2.54, " ") | Q16: =IF(E16>0.1,K16/18," ") | R16: =IF(E16>0.1,Q16*E16," ")
L17: =IF(Table11524[[#This Row],[Q]]>0.1, Table11524[[#This Row],[Q]]*Table11524[[#This Row],[$MXN OUT]], " ") | M17: =IF(Table11524[[#This Row],[Q]]>0.1,F17*2.20462, " ") | N17: =IF(Table11524[[#This Row],[Q]]>0.1,G17/2.54, " ") | O17: =IF(Table11524[[#This Row],[Q]]>0.1, H17/2.54, " ") | P17: =IF(Table11524[[#This Row],[Q]]>0.1,I17/2.54, " ") | Q17: =IF(E17>0.1,K17/18," ") | R17: =IF(E17>0.1,Q17*E17," ")
L18: =IF(Table11524[[#This Row],[Q]]>0.1, Table11524[[#This Row],[Q]]*Table11524[[#This Row],[$MXN OUT]], " ") | M18: =IF(Table11524[[#This Row],[Q]]>0.1,F18*2.20462, " ") | N18: =IF(Table11524[[#This Row],[Q]]>0.1,G18/2.54, " ") | O18: =IF(Table11524[[#This Row],[Q]]>0.1, H18/2.54, " ") | P18: =IF(Table11524[[#This Row],[Q]]>0.1,I18/2.54, " ") | Q18: =IF(E18>0.1,K18/18," ") | R18: =IF(E18>0.1,Q18*E18," ")
L19: =IF(Table11524[[#This Row],[Q]]>0.1, Table11524[[#This Row],[Q]]*Table11524[[#This Row],[$MXN OUT]], " ") | M19: =IF(Table11524[[#This Row],[Q]]>0.1,F19*2.20462, " ") | N19: =IF(Table11524[[#This Row],[Q]]>0.1,G19/2.54, " ") | O19: =IF(Table11524[[#This Row],[Q]]>0.1, H19/2.54, " ") | P19: =IF(Table11524[[#This Row],[Q]]>0.1,I19/2.54, " ") | Q19: =IF(E19>0.1,K19/18," ") | R19: =IF(E19>0.1,Q19*E19," ")
L20: =IF(Table11524[[#This Row],[Q]]>0.1, Table11524[[#This Row],[Q]]*Table11524[[#This Row],[$MXN OUT]], " ") | M20: =IF(Table11524[[#This Row],[Q]]>0.1,F20*2.20462, " ") | N20: =IF(Table11524[[#This Row],[Q]]>0.1,G20/2.54, " ") | O20: =IF(Table11524[[#This Row],[Q]]>0.1, H20/2.54, " ") | P20: =IF(Table11524[[#This Row],[Q]]>0.1,I20/2.54, " ") | Q20: =IF(E20>0.1,K20/18," ") | R20: =IF(E20>0.1,Q20*E20," ")
L21: =IF(Table11524[[#This Row],[Q]]>0.1, Table11524[[#This Row],[Q]]*Table11524[[#This Row],[$MXN OUT]], " ") | M21: =IF(Table11524[[#This Row],[Q]]>0.1,F21*2.20462, " ") | N21: =IF(Table11524[[#This Row],[Q]]>0.1,G21/2.54, " ") | O21: =IF(Table11524[[#This Row],[Q]]>0.1, H21/2.54, " ") | P21: =IF(Table11524[[#This Row],[Q]]>0.1,I21/2.54, " ") | Q21: =IF(E21>0.1,K21/18," ") | R21: =IF(E21>0.1,Q21*E21," ")
L22: =IF(Table11524[[#This Row],[Q]]>0.1, Table11524[[#This Row],[Q]]*Table11524[[#This Row],[$MXN OUT]], " ") | M22: =IF(Table11524[[#This Row],[Q]]>0.1,F22*2.20462, " ") | N22: =IF(Table11524[[#This Row],[Q]]>0.1,G22/2.54, " ") | O22: =IF(Table11524[[#This Row],[Q]]>0.1, H22/2.54, " ") | P22: =IF(Table11524[[#This Row],[Q]]>0.1,I22/2.54, " ") | Q22: =IF(E22>0.1,K22/18," ") | R22: =IF(E22>0.1,Q22*E22," ")
L23: =IF(Table11524[[#This Row],[Q]]>0.1, Table11524[[#This Row],[Q]]*Table11524[[#This Row],[$MXN OUT]], " ") | M23: =IF(Table11524[[#This Row],[Q]]>0.1,F23*2.20462, " ") | N23: =IF(Table11524[[#This Row],[Q]]>0.1,G23/2.54, " ") | O23: =IF(Table11524[[#This Row],[Q]]>0.1, H23/2.54, " ") | P23: =IF(Table11524[[#This Row],[Q]]>0.1,I23/2.54, " ") | Q23: =IF(E23>0.1,K23/18," ") | R23: =IF(E23>0.1,Q23*E23," ")
L24: =IF(Table11524[[#This Row],[Q]]>0.1, Table11524[[#This Row],[Q]]*Table11524[[#This Row],[$MXN OUT]], " ") | M24: =IF(Table11524[[#This Row],[Q]]>0.1,F24*2.20462, " ") | N24: =IF(Table11524[[#This Row],[Q]]>0.1,G24/2.54, " ") | O24: =IF(Table11524[[#This Row],[Q]]>0.1, H24/2.54, " ") | P24: =IF(Table11524[[#This Row],[Q]]>0.1,I24/2.54, " ") | Q24: =IF(E24>0.1,K24/18," ") | R24: =IF(E24>0.1,Q24*E24," ")
L25: =IF(Table11524[[#This Row],[Q]]>0.1, Table11524[[#This Row],[Q]]*Table11524[[#This Row],[$MXN OUT]], " ") | M25: =IF(Table11524[[#This Row],[Q]]>0.1,F25*2.20462, " ") | N25: =IF(Table11524[[#This Row],[Q]]>0.1,G25/2.54, " ") | O25: =IF(Table11524[[#This Row],[Q]]>0.1, H25/2.54, " ") | P25: =IF(Table11524[[#This Row],[Q]]>0.1,I25/2.54, " ") | Q25: =IF(E25>0.1,K25/18," ") | R25: =IF(E25>0.1,Q25*E25," ")
L26: =IF(Table11524[[#This Row],[Q]]>0.1, Table11524[[#This Row],[Q]]*Table11524[[#This Row],[$MXN OUT]], " ") | M26: =IF(Table11524[[#This Row],[Q]]>0.1,F26*2.20462, " ") | N26: =IF(Table11524[[#This Row],[Q]]>0.1,G26/2.54, " ") | O26: =IF(Table11524[[#This Row],[Q]]>0.1, H26/2.54, " ") | P26: =IF(Table11524[[#This Row],[Q]]>0.1,I26/2.54, " ") | Q26: =IF(E26>0.1,K26/18," ") | R26: =IF(E26>0.1,Q26*E26," ")
... L140: =IF(Table11524[[#This Row],[Q]]>0.1, Table11524[[#This Row],[Q]]*Table11524[[#This Row],[$MXN OUT]], " ") | M140: =IF(Table11524[[#This Row],[Q]]>0.1,F140*2.20462, " ") | N140: =IF(Table11524[[#This Row],[Q]]>0.1,G140/2.54, " ") | O140: =IF(Table11524[[#This Row],[Q]]>0.1, H140/2.54, " ") | P140: =IF(Table11524[[#This Row],[Q]]>0.1,I140/2.54, " ") | Q140: =IF(E140>0.1,K140/18," ") | R140: =IF(E140>0.1,Q140*E140," ")

Sheet -PayLog
A1: REQ DATE | B1: TYPE | C1: VENDOR | D1: ACCOUNT | E1: MXN | F1: TAX / COM | G1: TOTAL | H1: DESCRIPTION | I1: NOTES | J1: PAY DATE
A2: 46067 | B2: EXPENSE | D2: BBVA RAMSES | E2: 5900 | F2: =IF(Table3[[#This Row],[MXN]]>0.1, Table3[[#This Row],[MXN]]*0.16, " ") -> 944 | G2: =IF(Table3[[#This Row],[MXN]]>0.1, Table3[[#This Row],[MXN]]+Table3[[#This Row],[TAX / COM]], " ") -> 6844 | H2: MONTLY EXPENSES
A3: 46067 | B3: EXPENSE | D3: BBVA MARTHA | E3: 1600 | F3: =IF(Table3[[#This Row],[MXN]]>0.1, Table3[[#This Row],[MXN]]*0.8, " ") -> 1280 | G3: =IF(Table3[[#This Row],[MXN]]>0.1, Table3[[#This Row],[MXN]]+Table3[[#This Row],[TAX / COM]], " ") -> 2880 | H3: BANK FEE
A4: 46067 | B4: EXPENSE | D4: BOA EMPLOYEE | E4: 15500 | F4: =IF(Table3[[#This Row],[MXN]]>0.1, Table3[[#This Row],[MXN]]*0.1+69.5*2, " ") -> 1689 | G4: =IF(Table3[[#This Row],[MXN]]>0.1, Table3[[#This Row],[MXN]]+Table3[[#This Row],[TAX / COM]], " ") -> 17189 | H4: RENTS
A5: 46067 | B5: PRODUCTION | C5: AN (Angel Cabrera) | D5: BOA EMPLOYEE | E5: 13500 | F5: =IF(Table3[[#This Row],[MXN]]>0.1, Table3[[#This Row],[MXN]]*0.1+69.5*2, " ") -> 1489 | G5: =IF(Table3[[#This Row],[MXN]]>0.1, Table3[[#This Row],[MXN]]+Table3[[#This Row],[TAX / COM]], " ") -> 14989 | H5: ADVANCE S FOUNTAIN
A6: 46067 | B6: PRODUCTION | C6: CA (Carlos Arenas) | D6: BOA EMPLOYEE | E6: 20000 | F6: =IF(Table3[[#This Row],[MXN]]>0.1, Table3[[#This Row],[MXN]]*0.1+69.5*2, " ") -> 2139 | G6: =IF(Table3[[#This Row],[MXN]]>0.1, Table3[[#This Row],[MXN]]+Table3[[#This Row],[TAX / COM]], " ") -> 22139 | H6: ADVANCE CACTUS
G7: =IF(Table3[[#This Row],[MXN]]>0.1, Table3[[#This Row],[MXN]]+Table3[[#This Row],[TAX / COM]], " ")
G8: =IF(Table3[[#This Row],[MXN]]>0.1, Table3[[#This Row],[MXN]]+Table3[[#This Row],[TAX / COM]], " ")
G9: =IF(Table3[[#This Row],[MXN]]>0.1, Table3[[#This Row],[MXN]]+Table3[[#This Row],[TAX / COM]], " ")
G10: =IF(Table3[[#This Row],[MXN]]>0.1, Table3[[#This Row],[MXN]]+Table3[[#This Row],[TAX / COM]], " ")
G11: =IF(Table3[[#This Row],[MXN]]>0.1, Table3[[#This Row],[MXN]]+Table3[[#This Row],[TAX / COM]], " ")
G12: =IF(Table3[[#This Row],[MXN]]>0.1, Table3[[#This Row],[MXN]]+Table3[[#This Row],[TAX / COM]], " ")
G13: =IF(Table3[[#This Row],[MXN]]>0.1, Table3[[#This Row],[MXN]]+Table3[[#This Row],[TAX / COM]], " ")
G14: =IF(Table3[[#This Row],[MXN]]>0.1, Table3[[#This Row],[MXN]]+Table3[[#This Row],[TAX / COM]], " ")
G15: =IF(Table3[[#This Row],[MXN]]>0.1, Table3[[#This Row],[MXN]]+Table3[[#This Row],[TAX / COM]], " ")
G16: =IF(Table3[[#This Row],[MXN]]>0.1, Table3[[#This Row],[MXN]]+Table3[[#This Row],[TAX / COM]], " ")
G17: =IF(Table3[[#This Row],[MXN]]>0.1, Table3[[#This Row],[MXN]]+Table3[[#This Row],[TAX / COM]], " ")
G18: =IF(Table3[[#This Row],[MXN]]>0.1, Table3[[#This Row],[MXN]]+Table3[[#This Row],[TAX / COM]], " ")
... G200: =IF(Table3[[#This Row],[MXN]]>0.1, Table3[[#This Row],[MXN]]+Table3[[#This Row],[TAX / COM]], " ")

Sheet JM
A1: JM | B1: JOSE MEZA | C1: Book # | D1: 326 | G1: =SUM(Inventory_List_Table341115[Q]) -> 0 | K1: Rate | L1: 18 | M1: =SUM(Inventory_List_Table341115[TOTAL PESOS]) -> 0 | W1: =SUM(Inventory_List_Table341115[TOTAL USD]) -> 0
A2: # | B2: DATE | C2: COLOR / MATERIAL | D2: OBJECT/ SHAPE | E2: TYPE | F2: TAG-ID | G2: Q | H2: KG | I2: H CM | J2: W CM | K2: D CM | L2: PRICE | M2: TOTAL PESOS | N2: POUNDS | O2: H Inches | P2: W Inches | Q2: D Incbes | R2: AQ USD | S2: AQ RND USD | T2: LND USD | U2: LND RND USD | V2: RETAIL USD | W2: TOTAL USD | X2: AQC | Y2: LC | Z2: SQCM MXN | AA2: SQM MXN | AB2: TRK
A3: 1 | F3: =IF(Inventory_List_Table341115[[#This Row],[Q]]<0.1, " ",$A$1&$D$1&Inventory_List_Table341115[[#This Row],['#]]&Inventory_List_Table341115[[#This Row],[LC]]) | M3: =IF(Inventory_List_Table341115[[#This Row],[Q]]<0.1, " ", Inventory_List_Table341115[[#This Row],[Q]]*Inventory_List_Table341115[[#This Row],[PRICE]]) | N3: =IF(Inventory_List_Table341115[[#This Row],[Q]]<0.1, " ", Inventory_List_Table341115[[#This Row],[KG]]*2.20462) | O3: =IF(Inventory_List_Table341115[[#This Row],[Q]]<0.1, " ",Inventory_List_Table341115[[#This Row],[H CM]]/2.54) | P3: =IF(Inventory_List_Table341115[[#This Row],[Q]]<0.1, " ",Inventory_List_Table341115[[#This Row],[W CM]]/2.54) | Q3: =IF(Inventory_List_Table341115[[#This Row],[Q]]<0.1, " ",Inventory_List_Table341115[[#This Row],[D CM ]]/2.54) | R3: =IF(Inventory_List_Table341115[[#This Row],[Q]]<0.1, " ",Inventory_List_Table341115[[#This Row],[PRICE]]/$L$1) | S3: =IF(Inventory_List_Table341115[[#This Row],[Q]]<0.1, " ",IF(MOD(Inventory_List_Table341115[[#This Row],[AQ USD]],1)>0.4,ROUNDUP(Inventory_List_Table341115[[#This Row],[AQ USD]],0),ROUNDDOWN(Inventory_List_Table341115[[#This Row],[AQ USD]],0))) | T3: =IF(Inventory_List_Table341115[[#This Row],[Q]]<0.1, " ",Inventory_List_Table341115[[#This Row],[AQ RND USD]]*1.4) | U3: =IF(Inventory_List_Table341115[[#This Row],[Q]]<0.1, " ",IF(MOD(Inventory_List_Table341115[[#This Row],[LND USD]],1)>0.4,ROUNDUP(Inventory_List_Table341115[[#This Row],[LND USD]],0),ROUNDDOWN(Inventory_List_Table341115[[#This Row],[LND USD]],0))) | V3: =IF(Inventory_List_Table341115[[#This Row],[Q]]<0.1, " ",Inventory_List_Table341115[[#This Row],[LND RND USD]]*12) | W3: =IF(Inventory_List_Table341115[[#This Row],[Q]]<0.1, " ",Inventory_List_Table341115[[#This Row],[AQ USD]]) | X3: =IF(Inventory_List_Table341115[[#This Row],[Q]]<0.1, " ",SUBSTITUTE(SUBSTITUTE(SUBSTITUTE(SUBSTITUTE(SUBSTITUTE(SUBSTITUTE(SUBSTITUTE(SUBSTITUTE(SUBSTITUTE(SUBSTITUTE(Inventory_List_Table341115[[#This Row],[AQ RND USD]], "1", "M"), "2", "O"), "3", "X"), "4", "H"), "5", "E"), "6", "L"), "7", "F"), "8", "A"), "9", "N"), "0", "D")) | Y3: =IF(Inventory_List_Table341115[[#This Row],[Q]]<0.1, " ",SUBSTITUTE(SUBSTITUTE(SUBSTITUTE(SUBSTITUTE(SUBSTITUTE(SUBSTITUTE(SUBSTITUTE(SUBSTITUTE(SUBSTITUTE(SUBSTITUTE(Inventory_List_Table341115[[#This Row],[LND RND USD]], "1", "M"), "2", "O"), "3", "X"), "4", "H"), "5", "E"), "6", "L"), "7", "F"), "8", "A"), "9", "N"), "0", "D")) | Z3: =IF(Inventory_List_Table341115[[#This Row],[Q]]<0.1, " ",Inventory_List_Table341115[[#This Row],[H CM]]*Inventory_List_Table341115[[#This Row],[D CM ]]*4+Inventory_List_Table341115[[#This Row],[W CM]]*Inventory_List_Table341115[[#This Row],[D CM ]]/10000) | AA3: =IF(Inventory_List_Table341115[[#This Row],[Q]]<0.1, " ",Inventory_List_Table341115[[#This Row],[PRICE]]/Z3*10000)
A4: 2 | F4: =IF(Inventory_List_Table341115[[#This Row],[Q]]<0.1, " ",$A$1&$D$1&Inventory_List_Table341115[[#This Row],['#]]&Inventory_List_Table341115[[#This Row],[LC]]) | M4: =IF(Inventory_List_Table341115[[#This Row],[Q]]<0.1, " ", Inventory_List_Table341115[[#This Row],[Q]]*Inventory_List_Table341115[[#This Row],[PRICE]]) | N4: =IF(Inventory_List_Table341115[[#This Row],[Q]]<0.1, " ", Inventory_List_Table341115[[#This Row],[KG]]*2.20462) | O4: =IF(Inventory_List_Table341115[[#This Row],[Q]]<0.1, " ",Inventory_List_Table341115[[#This Row],[H CM]]/2.54) | P4: =IF(Inventory_List_Table341115[[#This Row],[Q]]<0.1, " ",Inventory_List_Table341115[[#This Row],[W CM]]/2.54) | Q4: =IF(Inventory_List_Table341115[[#This Row],[Q]]<0.1, " ",Inventory_List_Table341115[[#This Row],[D CM ]]/2.54) | R4: =IF(Inventory_List_Table341115[[#This Row],[Q]]<0.1, " ",Inventory_List_Table341115[[#This Row],[PRICE]]/$L$1) | S4: =IF(Inventory_List_Table341115[[#This Row],[Q]]<0.1, " ",IF(MOD(Inventory_List_Table341115[[#This Row],[AQ USD]],1)>0.4,ROUNDUP(Inventory_List_Table341115[[#This Row],[AQ USD]],0),ROUNDDOWN(Inventory_List_Table341115[[#This Row],[AQ USD]],0))) | T4: =IF(Inventory_List_Table341115[[#This Row],[Q]]<0.1, " ",Inventory_List_Table341115[[#This Row],[AQ RND USD]]*1.4) | U4: =IF(Inventory_List_Table341115[[#This Row],[Q]]<0.1, " ",IF(MOD(Inventory_List_Table341115[[#This Row],[LND USD]],1)>0.4,ROUNDUP(Inventory_List_Table341115[[#This Row],[LND USD]],0),ROUNDDOWN(Inventory_List_Table341115[[#This Row],[LND USD]],0))) | V4: =IF(Inventory_List_Table341115[[#This Row],[Q]]<0.1, " ",Inventory_List_Table341115[[#This Row],[LND RND USD]]*12) | W4: =IF(Inventory_List_Table341115[[#This Row],[Q]]<0.1, " ",Inventory_List_Table341115[[#This Row],[AQ USD]]) | X4: =IF(Inventory_List_Table341115[[#This Row],[Q]]<0.1, " ",SUBSTITUTE(SUBSTITUTE(SUBSTITUTE(SUBSTITUTE(SUBSTITUTE(SUBSTITUTE(SUBSTITUTE(SUBSTITUTE(SUBSTITUTE(SUBSTITUTE(Inventory_List_Table341115[[#This Row],[AQ RND USD]], "1", "M"), "2", "O"), "3", "X"), "4", "H"), "5", "E"), "6", "L"), "7", "F"), "8", "A"), "9", "N"), "0", "D")) | Y4: =IF(Inventory_List_Table341115[[#This Row],[Q]]<0.1, " ",SUBSTITUTE(SUBSTITUTE(SUBSTITUTE(SUBSTITUTE(SUBSTITUTE(SUBSTITUTE(SUBSTITUTE(SUBSTITUTE(SUBSTITUTE(SUBSTITUTE(Inventory_List_Table341115[[#This Row],[LND RND USD]], "1", "M"), "2", "O"), "3", "X"), "4", "H"), "5", "E"), "6", "L"), "7", "F"), "8", "A"), "9", "N"), "0", "D")) | Z4: =IF(Inventory_List_Table341115[[#This Row],[Q]]<0.1, " ",Inventory_List_Table341115[[#This Row],[H CM]]*Inventory_List_Table341115[[#This Row],[D CM ]]*4+Inventory_List_Table341115[[#This Row],[W CM]]*Inventory_List_Table341115[[#This Row],[D CM ]]/10000) | AA4: =IF(Inventory_List_Table341115[[#This Row],[Q]]<0.1, " ",Inventory_List_Table341115[[#This Row],[PRICE]]/Z4*10000)
A5: 3 | F5: =IF(Inventory_List_Table341115[[#This Row],[Q]]<0.1, " ",$A$1&$D$1&Inventory_List_Table341115[[#This Row],['#]]&Inventory_List_Table341115[[#This Row],[LC]]) | M5: =IF(Inventory_List_Table341115[[#This Row],[Q]]<0.1, " ", Inventory_List_Table341115[[#This Row],[Q]]*Inventory_List_Table341115[[#This Row],[PRICE]]) | N5: =IF(Inventory_List_Table341115[[#This Row],[Q]]<0.1, " ", Inventory_List_Table341115[[#This Row],[KG]]*2.20462) | O5: =IF(Inventory_List_Table341115[[#This Row],[Q]]<0.1, " ",Inventory_List_Table341115[[#This Row],[H CM]]/2.54) | P5: =IF(Inventory_List_Table341115[[#This Row],[Q]]<0.1, " ",Inventory_List_Table341115[[#This Row],[W CM]]/2.54) | Q5: =IF(Inventory_List_Table341115[[#This Row],[Q]]<0.1, " ",Inventory_List_Table341115[[#This Row],[D CM ]]/2.54) | R5: =IF(Inventory_List_Table341115[[#This Row],[Q]]<0.1, " ",Inventory_List_Table341115[[#This Row],[PRICE]]/$L$1) | S5: =IF(Inventory_List_Table341115[[#This Row],[Q]]<0.1, " ",IF(MOD(Inventory_List_Table341115[[#This Row],[AQ USD]],1)>0.4,ROUNDUP(Inventory_List_Table341115[[#This Row],[AQ USD]],0),ROUNDDOWN(Inventory_List_Table341115[[#This Row],[AQ USD]],0))) | T5: =IF(Inventory_List_Table341115[[#This Row],[Q]]<0.1, " ",Inventory_List_Table341115[[#This Row],[AQ RND USD]]*1.4) | U5: =IF(Inventory_List_Table341115[[#This Row],[Q]]<0.1, " ",IF(MOD(Inventory_List_Table341115[[#This Row],[LND USD]],1)>0.4,ROUNDUP(Inventory_List_Table341115[[#This Row],[LND USD]],0),ROUNDDOWN(Inventory_List_Table341115[[#This Row],[LND USD]],0))) | V5: =IF(Inventory_List_Table341115[[#This Row],[Q]]<0.1, " ",Inventory_List_Table341115[[#This Row],[LND RND USD]]*12) | W5: =IF(Inventory_List_Table341115[[#This Row],[Q]]<0.1, " ",Inventory_List_Table341115[[#This Row],[AQ USD]]) | X5: =IF(Inventory_List_Table341115[[#This Row],[Q]]<0.1, " ",SUBSTITUTE(SUBSTITUTE(SUBSTITUTE(SUBSTITUTE(SUBSTITUTE(SUBSTITUTE(SUBSTITUTE(SUBSTITUTE(SUBSTITUTE(SUBSTITUTE(Inventory_List_Table341115[[#This Row],[AQ RND USD]], "1", "M"), "2", "O"), "3", "X"), "4", "H"), "5", "E"), "6", "L"), "7", "F"), "8", "A"), "9", "N"), "0", "D")) | Y5: =IF(Inventory_List_Table341115[[#This Row],[Q]]<0.1, " ",SUBSTITUTE(SUBSTITUTE(SUBSTITUTE(SUBSTITUTE(SUBSTITUTE(SUBSTITUTE(SUBSTITUTE(SUBSTITUTE(SUBSTITUTE(SUBSTITUTE(Inventory_List_Table341115[[#This Row],[LND RND USD]], "1", "M"), "2", "O"), "3", "X"), "4", "H"), "5", "E"), "6", "L"), "7", "F"), "8", "A"), "9", "N"), "0", "D")) | Z5: =IF(Inventory_List_Table341115[[#This Row],[Q]]<0.1, " ",Inventory_List_Table341115[[#This Row],[H CM]]*Inventory_List_Table341115[[#This Row],[D CM ]]*4+Inventory_List_Table341115[[#This Row],[W CM]]*Inventory_List_Table341115[[#This Row],[D CM ]]/10000) | AA5: =IF(Inventory_List_Table341115[[#This Row],[Q]]<0.1, " ",Inventory_List_Table341115[[#This Row],[PRICE]]/Z5*10000)
A6: 4 | F6: =IF(Inventory_List_Table341115[[#This Row],[Q]]<0.1, " ",$A$1&$D$1&Inventory_List_Table341115[[#This Row],['#]]&Inventory_List_Table341115[[#This Row],[LC]]) | M6: =IF(Inventory_List_Table341115[[#This Row],[Q]]<0.1, " ", Inventory_List_Table341115[[#This Row],[Q]]*Inventory_List_Table341115[[#This Row],[PRICE]]) | N6: =IF(Inventory_List_Table341115[[#This Row],[Q]]<0.1, " ", Inventory_List_Table341115[[#This Row],[KG]]*2.20462) | O6: =IF(Inventory_List_Table341115[[#This Row],[Q]]<0.1, " ",Inventory_List_Table341115[[#This Row],[H CM]]/2.54) | P6: =IF(Inventory_List_Table341115[[#This Row],[Q]]<0.1, " ",Inventory_List_Table341115[[#This Row],[W CM]]/2.54) | Q6: =IF(Inventory_List_Table341115[[#This Row],[Q]]<0.1, " ",Inventory_List_Table341115[[#This Row],[D CM ]]/2.54) | R6: =IF(Inventory_List_Table341115[[#This Row],[Q]]<0.1, " ",Inventory_List_Table341115[[#This Row],[PRICE]]/$L$1) | S6: =IF(Inventory_List_Table341115[[#This Row],[Q]]<0.1, " ",IF(MOD(Inventory_List_Table341115[[#This Row],[AQ USD]],1)>0.4,ROUNDUP(Inventory_List_Table341115[[#This Row],[AQ USD]],0),ROUNDDOWN(Inventory_List_Table341115[[#This Row],[AQ USD]],0))) | T6: =IF(Inventory_List_Table341115[[#This Row],[Q]]<0.1, " ",Inventory_List_Table341115[[#This Row],[AQ RND USD]]*1.4) | U6: =IF(Inventory_List_Table341115[[#This Row],[Q]]<0.1, " ",IF(MOD(Inventory_List_Table341115[[#This Row],[LND USD]],1)>0.4,ROUNDUP(Inventory_List_Table341115[[#This Row],[LND USD]],0),ROUNDDOWN(Inventory_List_Table341115[[#This Row],[LND USD]],0))) | V6: =IF(Inventory_List_Table341115[[#This Row],[Q]]<0.1, " ",Inventory_List_Table341115[[#This Row],[LND RND USD]]*12) | W6: =IF(Inventory_List_Table341115[[#This Row],[Q]]<0.1, " ",Inventory_List_Table341115[[#This Row],[AQ USD]]) | X6: =IF(Inventory_List_Table341115[[#This Row],[Q]]<0.1, " ",SUBSTITUTE(SUBSTITUTE(SUBSTITUTE(SUBSTITUTE(SUBSTITUTE(SUBSTITUTE(SUBSTITUTE(SUBSTITUTE(SUBSTITUTE(SUBSTITUTE(Inventory_List_Table341115[[#This Row],[AQ RND USD]], "1", "M"), "2", "O"), "3", "X"), "4", "H"), "5", "E"), "6", "L"), "7", "F"), "8", "A"), "9", "N"), "0", "D")) | Y6: =IF(Inventory_List_Table341115[[#This Row],[Q]]<0.1, " ",SUBSTITUTE(SUBSTITUTE(SUBSTITUTE(SUBSTITUTE(SUBSTITUTE(SUBSTITUTE(SUBSTITUTE(SUBSTITUTE(SUBSTITUTE(SUBSTITUTE(Inventory_List_Table341115[[#This Row],[LND RND USD]], "1", "M"), "2", "O"), "3", "X"), "4", "H"), "5", "E"), "6", "L"), "7", "F"), "8", "A"), "9", "N"), "0", "D")) | Z6: =IF(Inventory_List_Table341115[[#This Row],[Q]]<0.1, " ",Inventory_List_Table341115[[#This Row],[H CM]]*Inventory_List_Table341115[[#This Row],[D CM ]]*4+Inventory_List_Table341115[[#This Row],[W CM]]*Inventory_List_Table341115[[#This Row],[D CM ]]/10000) | AA6: =IF(Inventory_List_Table341115[[#This Row],[Q]]<0.1, " ",Inventory_List_Table341115[[#This Row],[PRICE]]/Z6*10000)
A7: 5 | F7: =IF(Inventory_List_Table341115[[#This Row],[Q]]<0.1, " ",$A$1&$D$1&Inventory_List_Table341115[[#This Row],['#]]&Inventory_List_Table341115[[#This Row],[LC]]) | M7: =IF(Inventory_List_Table341115[[#This Row],[Q]]<0.1, " ", Inventory_List_Table341115[[#This Row],[Q]]*Inventory_List_Table341115[[#This Row],[PRICE]]) | N7: =IF(Inventory_List_Table341115[[#This Row],[Q]]<0.1, " ", Inventory_List_Table341115[[#This Row],[KG]]*2.20462) | O7: =IF(Inventory_List_Table341115[[#This Row],[Q]]<0.1, " ",Inventory_List_Table341115[[#This Row],[H CM]]/2.54) | P7: =IF(Inventory_List_Table341115[[#This Row],[Q]]<0.1, " ",Inventory_List_Table341115[[#This Row],[W CM]]/2.54) | Q7: =IF(Inventory_List_Table341115[[#This Row],[Q]]<0.1, " ",Inventory_List_Table341115[[#This Row],[D CM ]]/2.54) | R7: =IF(Inventory_List_Table341115[[#This Row],[Q]]<0.1, " ",Inventory_List_Table341115[[#This Row],[PRICE]]/$L$1) | S7: =IF(Inventory_List_Table341115[[#This Row],[Q]]<0.1, " ",IF(MOD(Inventory_List_Table341115[[#This Row],[AQ USD]],1)>0.4,ROUNDUP(Inventory_List_Table341115[[#This Row],[AQ USD]],0),ROUNDDOWN(Inventory_List_Table341115[[#This Row],[AQ USD]],0))) | T7: =IF(Inventory_List_Table341115[[#This Row],[Q]]<0.1, " ",Inventory_List_Table341115[[#This Row],[AQ RND USD]]*1.4) | U7: =IF(Inventory_List_Table341115[[#This Row],[Q]]<0.1, " ",IF(MOD(Inventory_List_Table341115[[#This Row],[LND USD]],1)>0.4,ROUNDUP(Inventory_List_Table341115[[#This Row],[LND USD]],0),ROUNDDOWN(Inventory_List_Table341115[[#This Row],[LND USD]],0))) | V7: =IF(Inventory_List_Table341115[[#This Row],[Q]]<0.1, " ",Inventory_List_Table341115[[#This Row],[LND RND USD]]*12) | W7: =IF(Inventory_List_Table341115[[#This Row],[Q]]<0.1, " ",Inventory_List_Table341115[[#This Row],[AQ USD]]) | X7: =IF(Inventory_List_Table341115[[#This Row],[Q]]<0.1, " ",SUBSTITUTE(SUBSTITUTE(SUBSTITUTE(SUBSTITUTE(SUBSTITUTE(SUBSTITUTE(SUBSTITUTE(SUBSTITUTE(SUBSTITUTE(SUBSTITUTE(Inventory_List_Table341115[[#This Row],[AQ RND USD]], "1", "M"), "2", "O"), "3", "X"), "4", "H"), "5", "E"), "6", "L"), "7", "F"), "8", "A"), "9", "N"), "0", "D")) | Y7: =IF(Inventory_List_Table341115[[#This Row],[Q]]<0.1, " ",SUBSTITUTE(SUBSTITUTE(SUBSTITUTE(SUBSTITUTE(SUBSTITUTE(SUBSTITUTE(SUBSTITUTE(SUBSTITUTE(SUBSTITUTE(SUBSTITUTE(Inventory_List_Table341115[[#This Row],[LND RND USD]], "1", "M"), "2", "O"), "3", "X"), "4", "H"), "5", "E"), "6", "L"), "7", "F"), "8", "A"), "9", "N"), "0", "D")) | Z7: =IF(Inventory_List_Table341115[[#This Row],[Q]]<0.1, " ",Inventory_List_Table341115[[#This Row],[H CM]]*Inventory_List_Table341115[[#This Row],[D CM ]]*4+Inventory_List_Table341115[[#This Row],[W CM]]*Inventory_List_Table341115[[#This Row],[D CM ]]/10000) | AA7: =IF(Inventory_List_Table341115[[#This Row],[Q]]<0.1, " ",Inventory_List_Table341115[[#This Row],[PRICE]]/Z7*10000)
A8: 6 | F8: =IF(Inventory_List_Table341115[[#This Row],[Q]]<0.1, " ",$A$1&$D$1&Inventory_List_Table341115[[#This Row],['#]]&Inventory_List_Table341115[[#This Row],[LC]]) | M8: =IF(Inventory_List_Table341115[[#This Row],[Q]]<0.1, " ", Inventory_List_Table341115[[#This Row],[Q]]*Inventory_List_Table341115[[#This Row],[PRICE]]) | N8: =IF(Inventory_List_Table341115[[#This Row],[Q]]<0.1, " ", Inventory_List_Table341115[[#This Row],[KG]]*2.20462) | O8: =IF(Inventory_List_Table341115[[#This Row],[Q]]<0.1, " ",Inventory_List_Table341115[[#This Row],[H CM]]/2.54) | P8: =IF(Inventory_List_Table341115[[#This Row],[Q]]<0.1, " ",Inventory_List_Table341115[[#This Row],[W CM]]/2.54) | Q8: =IF(Inventory_List_Table341115[[#This Row],[Q]]<0.1, " ",Inventory_List_Table341115[[#This Row],[D CM ]]/2.54) | R8: =IF(Inventory_List_Table341115[[#This Row],[Q]]<0.1, " ",Inventory_List_Table341115[[#This Row],[PRICE]]/$L$1) | S8: =IF(Inventory_List_Table341115[[#This Row],[Q]]<0.1, " ",IF(MOD(Inventory_List_Table341115[[#This Row],[AQ USD]],1)>0.4,ROUNDUP(Inventory_List_Table341115[[#This Row],[AQ USD]],0),ROUNDDOWN(Inventory_List_Table341115[[#This Row],[AQ USD]],0))) | T8: =IF(Inventory_List_Table341115[[#This Row],[Q]]<0.1, " ",Inventory_List_Table341115[[#This Row],[AQ RND USD]]*1.4) | U8: =IF(Inventory_List_Table341115[[#This Row],[Q]]<0.1, " ",IF(MOD(Inventory_List_Table341115[[#This Row],[LND USD]],1)>0.4,ROUNDUP(Inventory_List_Table341115[[#This Row],[LND USD]],0),ROUNDDOWN(Inventory_List_Table341115[[#This Row],[LND USD]],0))) | V8: =IF(Inventory_List_Table341115[[#This Row],[Q]]<0.1, " ",Inventory_List_Table341115[[#This Row],[LND RND USD]]*12) | W8: =IF(Inventory_List_Table341115[[#This Row],[Q]]<0.1, " ",Inventory_List_Table341115[[#This Row],[AQ USD]]) | X8: =IF(Inventory_List_Table341115[[#This Row],[Q]]<0.1, " ",SUBSTITUTE(SUBSTITUTE(SUBSTITUTE(SUBSTITUTE(SUBSTITUTE(SUBSTITUTE(SUBSTITUTE(SUBSTITUTE(SUBSTITUTE(SUBSTITUTE(Inventory_List_Table341115[[#This Row],[AQ RND USD]], "1", "M"), "2", "O"), "3", "X"), "4", "H"), "5", "E"), "6", "L"), "7", "F"), "8", "A"), "9", "N"), "0", "D")) | Y8: =IF(Inventory_List_Table341115[[#This Row],[Q]]<0.1, " ",SUBSTITUTE(SUBSTITUTE(SUBSTITUTE(SUBSTITUTE(SUBSTITUTE(SUBSTITUTE(SUBSTITUTE(SUBSTITUTE(SUBSTITUTE(SUBSTITUTE(Inventory_List_Table341115[[#This Row],[LND RND USD]], "1", "M"), "2", "O"), "3", "X"), "4", "H"), "5", "E"), "6", "L"), "7", "F"), "8", "A"), "9", "N"), "0", "D")) | Z8: =IF(Inventory_List_Table341115[[#This Row],[Q]]<0.1, " ",Inventory_List_Table341115[[#This Row],[H CM]]*Inventory_List_Table341115[[#This Row],[D CM ]]*4+Inventory_List_Table341115[[#This Row],[W CM]]*Inventory_List_Table341115[[#This Row],[D CM ]]/10000) | AA8: =IF(Inventory_List_Table341115[[#This Row],[Q]]<0.1, " ",Inventory_List_Table341115[[#This Row],[PRICE]]/Z8*10000)
A9: 7 | F9: =IF(Inventory_List_Table341115[[#This Row],[Q]]<0.1, " ",$A$1&$D$1&Inventory_List_Table341115[[#This Row],['#]]&Inventory_List_Table341115[[#This Row],[LC]]) | M9: =IF(Inventory_List_Table341115[[#This Row],[Q]]<0.1, " ", Inventory_List_Table341115[[#This Row],[Q]]*Inventory_List_Table341115[[#This Row],[PRICE]]) | N9: =IF(Inventory_List_Table341115[[#This Row],[Q]]<0.1, " ", Inventory_List_Table341115[[#This Row],[KG]]*2.20462) | O9: =IF(Inventory_List_Table341115[[#This Row],[Q]]<0.1, " ",Inventory_List_Table341115[[#This Row],[H CM]]/2.54) | P9: =IF(Inventory_List_Table341115[[#This Row],[Q]]<0.1, " ",Inventory_List_Table341115[[#This Row],[W CM]]/2.54) | Q9: =IF(Inventory_List_Table341115[[#This Row],[Q]]<0.1, " ",Inventory_List_Table341115[[#This Row],[D CM ]]/2.54) | R9: =IF(Inventory_List_Table341115[[#This Row],[Q]]<0.1, " ",Inventory_List_Table341115[[#This Row],[PRICE]]/$L$1) | S9: =IF(Inventory_List_Table341115[[#This Row],[Q]]<0.1, " ",IF(MOD(Inventory_List_Table341115[[#This Row],[AQ USD]],1)>0.4,ROUNDUP(Inventory_List_Table341115[[#This Row],[AQ USD]],0),ROUNDDOWN(Inventory_List_Table341115[[#This Row],[AQ USD]],0))) | T9: =IF(Inventory_List_Table341115[[#This Row],[Q]]<0.1, " ",Inventory_List_Table341115[[#This Row],[AQ RND USD]]*1.4) | U9: =IF(Inventory_List_Table341115[[#This Row],[Q]]<0.1, " ",IF(MOD(Inventory_List_Table341115[[#This Row],[LND USD]],1)>0.4,ROUNDUP(Inventory_List_Table341115[[#This Row],[LND USD]],0),ROUNDDOWN(Inventory_List_Table341115[[#This Row],[LND USD]],0))) | V9: =IF(Inventory_List_Table341115[[#This Row],[Q]]<0.1, " ",Inventory_List_Table341115[[#This Row],[LND RND USD]]*12) | W9: =IF(Inventory_List_Table341115[[#This Row],[Q]]<0.1, " ",Inventory_List_Table341115[[#This Row],[AQ USD]]) | X9: =IF(Inventory_List_Table341115[[#This Row],[Q]]<0.1, " ",SUBSTITUTE(SUBSTITUTE(SUBSTITUTE(SUBSTITUTE(SUBSTITUTE(SUBSTITUTE(SUBSTITUTE(SUBSTITUTE(SUBSTITUTE(SUBSTITUTE(Inventory_List_Table341115[[#This Row],[AQ RND USD]], "1", "M"), "2", "O"), "3", "X"), "4", "H"), "5", "E"), "6", "L"), "7", "F"), "8", "A"), "9", "N"), "0", "D")) | Y9: =IF(Inventory_List_Table341115[[#This Row],[Q]]<0.1, " ",SUBSTITUTE(SUBSTITUTE(SUBSTITUTE(SUBSTITUTE(SUBSTITUTE(SUBSTITUTE(SUBSTITUTE(SUBSTITUTE(SUBSTITUTE(SUBSTITUTE(Inventory_List_Table341115[[#This Row],[LND RND USD]], "1", "M"), "2", "O"), "3", "X"), "4", "H"), "5", "E"), "6", "L"), "7", "F"), "8", "A"), "9", "N"), "0", "D")) | Z9: =IF(Inventory_List_Table341115[[#This Row],[Q]]<0.1, " ",Inventory_List_Table341115[[#This Row],[H CM]]*Inventory_List_Table341115[[#This Row],[D CM ]]*4+Inventory_List_Table341115[[#This Row],[W CM]]*Inventory_List_Table341115[[#This Row],[D CM ]]/10000) | AA9: =IF(Inventory_List_Table341115[[#This Row],[Q]]<0.1, " ",Inventory_List_Table341115[[#This Row],[PRICE]]/Z9*10000)
A10: 8 | F10: =IF(Inventory_List_Table341115[[#This Row],[Q]]<0.1, " ",$A$1&$D$1&Inventory_List_Table341115[[#This Row],['#]]&Inventory_List_Table341115[[#This Row],[LC]]) | M10: =IF(Inventory_List_Table341115[[#This Row],[Q]]<0.1, " ", Inventory_List_Table341115[[#This Row],[Q]]*Inventory_List_Table341115[[#This Row],[PRICE]]) | N10: =IF(Inventory_List_Table341115[[#This Row],[Q]]<0.1, " ", Inventory_List_Table341115[[#This Row],[KG]]*2.20462) | O10: =IF(Inventory_List_Table341115[[#This Row],[Q]]<0.1, " ",Inventory_List_Table341115[[#This Row],[H CM]]/2.54) | P10: =IF(Inventory_List_Table341115[[#This Row],[Q]]<0.1, " ",Inventory_List_Table341115[[#This Row],[W CM]]/2.54) | Q10: =IF(Inventory_List_Table341115[[#This Row],[Q]]<0.1, " ",Inventory_List_Table341115[[#This Row],[D CM ]]/2.54) | R10: =IF(Inventory_List_Table341115[[#This Row],[Q]]<0.1, " ",Inventory_List_Table341115[[#This Row],[PRICE]]/$L$1) | S10: =IF(Inventory_List_Table341115[[#This Row],[Q]]<0.1, " ",IF(MOD(Inventory_List_Table341115[[#This Row],[AQ USD]],1)>0.4,ROUNDUP(Inventory_List_Table341115[[#This Row],[AQ USD]],0),ROUNDDOWN(Inventory_List_Table341115[[#This Row],[AQ USD]],0))) | T10: =IF(Inventory_List_Table341115[[#This Row],[Q]]<0.1, " ",Inventory_List_Table341115[[#This Row],[AQ RND USD]]*1.4) | U10: =IF(Inventory_List_Table341115[[#This Row],[Q]]<0.1, " ",IF(MOD(Inventory_List_Table341115[[#This Row],[LND USD]],1)>0.4,ROUNDUP(Inventory_List_Table341115[[#This Row],[LND USD]],0),ROUNDDOWN(Inventory_List_Table341115[[#This Row],[LND USD]],0))) | V10: =IF(Inventory_List_Table341115[[#This Row],[Q]]<0.1, " ",Inventory_List_Table341115[[#This Row],[LND RND USD]]*12) | W10: =IF(Inventory_List_Table341115[[#This Row],[Q]]<0.1, " ",Inventory_List_Table341115[[#This Row],[AQ USD]]) | X10: =IF(Inventory_List_Table341115[[#This Row],[Q]]<0.1, " ",SUBSTITUTE(SUBSTITUTE(SUBSTITUTE(SUBSTITUTE(SUBSTITUTE(SUBSTITUTE(SUBSTITUTE(SUBSTITUTE(SUBSTITUTE(SUBSTITUTE(Inventory_List_Table341115[[#This Row],[AQ RND USD]], "1", "M"), "2", "O"), "3", "X"), "4", "H"), "5", "E"), "6", "L"), "7", "F"), "8", "A"), "9", "N"), "0", "D")) | Y10: =IF(Inventory_List_Table341115[[#This Row],[Q]]<0.1, " ",SUBSTITUTE(SUBSTITUTE(SUBSTITUTE(SUBSTITUTE(SUBSTITUTE(SUBSTITUTE(SUBSTITUTE(SUBSTITUTE(SUBSTITUTE(SUBSTITUTE(Inventory_List_Table341115[[#This Row],[LND RND USD]], "1", "M"), "2", "O"), "3", "X"), "4", "H"), "5", "E"), "6", "L"), "7", "F"), "8", "A"), "9", "N"), "0", "D")) | Z10: =IF(Inventory_List_Table341115[[#This Row],[Q]]<0.1, " ",Inventory_List_Table341115[[#This Row],[H CM]]*Inventory_List_Table341115[[#This Row],[D CM ]]*4+Inventory_List_Table341115[[#This Row],[W CM]]*Inventory_List_Table341115[[#This Row],[D CM ]]/10000) | AA10: =IF(Inventory_List_Table341115[[#This Row],[Q]]<0.1, " ",Inventory_List_Table341115[[#This Row],[PRICE]]/Z10*10000)
A11: 9 | F11: =IF(Inventory_List_Table341115[[#This Row],[Q]]<0.1, " ",$A$1&$D$1&Inventory_List_Table341115[[#This Row],['#]]&Inventory_List_Table341115[[#This Row],[LC]]) | M11: =IF(Inventory_List_Table341115[[#This Row],[Q]]<0.1, " ", Inventory_List_Table341115[[#This Row],[Q]]*Inventory_List_Table341115[[#This Row],[PRICE]]) | N11: =IF(Inventory_List_Table341115[[#This Row],[Q]]<0.1, " ", Inventory_List_Table341115[[#This Row],[KG]]*2.20462) | O11: =IF(Inventory_List_Table341115[[#This Row],[Q]]<0.1, " ",Inventory_List_Table341115[[#This Row],[H CM]]/2.54) | P11: =IF(Inventory_List_Table341115[[#This Row],[Q]]<0.1, " ",Inventory_List_Table341115[[#This Row],[W CM]]/2.54) | Q11: =IF(Inventory_List_Table341115[[#This Row],[Q]]<0.1, " ",Inventory_List_Table341115[[#This Row],[D CM ]]/2.54) | R11: =IF(Inventory_List_Table341115[[#This Row],[Q]]<0.1, " ",Inventory_List_Table341115[[#This Row],[PRICE]]/$L$1) | S11: =IF(Inventory_List_Table341115[[#This Row],[Q]]<0.1, " ",IF(MOD(Inventory_List_Table341115[[#This Row],[AQ USD]],1)>0.4,ROUNDUP(Inventory_List_Table341115[[#This Row],[AQ USD]],0),ROUNDDOWN(Inventory_List_Table341115[[#This Row],[AQ USD]],0))) | T11: =IF(Inventory_List_Table341115[[#This Row],[Q]]<0.1, " ",Inventory_List_Table341115[[#This Row],[AQ RND USD]]*1.4) | U11: =IF(Inventory_List_Table341115[[#This Row],[Q]]<0.1, " ",IF(MOD(Inventory_List_Table341115[[#This Row],[LND USD]],1)>0.4,ROUNDUP(Inventory_List_Table341115[[#This Row],[LND USD]],0),ROUNDDOWN(Inventory_List_Table341115[[#This Row],[LND USD]],0))) | V11: =IF(Inventory_List_Table341115[[#This Row],[Q]]<0.1, " ",Inventory_List_Table341115[[#This Row],[LND RND USD]]*12) | W11: =IF(Inventory_List_Table341115[[#This Row],[Q]]<0.1, " ",Inventory_List_Table341115[[#This Row],[AQ USD]]) | X11: =IF(Inventory_List_Table341115[[#This Row],[Q]]<0.1, " ",SUBSTITUTE(SUBSTITUTE(SUBSTITUTE(SUBSTITUTE(SUBSTITUTE(SUBSTITUTE(SUBSTITUTE(SUBSTITUTE(SUBSTITUTE(SUBSTITUTE(Inventory_List_Table341115[[#This Row],[AQ RND USD]], "1", "M"), "2", "O"), "3", "X"), "4", "H"), "5", "E"), "6", "L"), "7", "F"), "8", "A"), "9", "N"), "0", "D")) | Y11: =IF(Inventory_List_Table341115[[#This Row],[Q]]<0.1, " ",SUBSTITUTE(SUBSTITUTE(SUBSTITUTE(SUBSTITUTE(SUBSTITUTE(SUBSTITUTE(SUBSTITUTE(SUBSTITUTE(SUBSTITUTE(SUBSTITUTE(Inventory_List_Table341115[[#This Row],[LND RND USD]], "1", "M"), "2", "O"), "3", "X"), "4", "H"), "5", "E"), "6", "L"), "7", "F"), "8", "A"), "9", "N"), "0", "D")) | Z11: =IF(Inventory_List_Table341115[[#This Row],[Q]]<0.1, " ",Inventory_List_Table341115[[#This Row],[H CM]]*Inventory_List_Table341115[[#This Row],[D CM ]]*4+Inventory_List_Table341115[[#This Row],[W CM]]*Inventory_List_Table341115[[#This Row],[D CM ]]/10000) | AA11: =IF(Inventory_List_Table341115[[#This Row],[Q]]<0.1, " ",Inventory_List_Table341115[[#This Row],[PRICE]]/Z11*10000)
A12: 10 | F12: =IF(Inventory_List_Table341115[[#This Row],[Q]]<0.1, " ",$A$1&$D$1&Inventory_List_Table341115[[#This Row],['#]]&Inventory_List_Table341115[[#This Row],[LC]]) | M12: =IF(Inventory_List_Table341115[[#This Row],[Q]]<0.1, " ", Inventory_List_Table341115[[#This Row],[Q]]*Inventory_List_Table341115[[#This Row],[PRICE]]) | N12: =IF(Inventory_List_Table341115[[#This Row],[Q]]<0.1, " ", Inventory_List_Table341115[[#This Row],[KG]]*2.20462) | O12: =IF(Inventory_List_Table341115[[#This Row],[Q]]<0.1, " ",Inventory_List_Table341115[[#This Row],[H CM]]/2.54) | P12: =IF(Inventory_List_Table341115[[#This Row],[Q]]<0.1, " ",Inventory_List_Table341115[[#This Row],[W CM]]/2.54) | Q12: =IF(Inventory_List_Table341115[[#This Row],[Q]]<0.1, " ",Inventory_List_Table341115[[#This Row],[D CM ]]/2.54) | R12: =IF(Inventory_List_Table341115[[#This Row],[Q]]<0.1, " ",Inventory_List_Table341115[[#This Row],[PRICE]]/$L$1) | S12: =IF(Inventory_List_Table341115[[#This Row],[Q]]<0.1, " ",IF(MOD(Inventory_List_Table341115[[#This Row],[AQ USD]],1)>0.4,ROUNDUP(Inventory_List_Table341115[[#This Row],[AQ USD]],0),ROUNDDOWN(Inventory_List_Table341115[[#This Row],[AQ USD]],0))) | T12: =IF(Inventory_List_Table341115[[#This Row],[Q]]<0.1, " ",Inventory_List_Table341115[[#This Row],[AQ RND USD]]*1.4) | U12: =IF(Inventory_List_Table341115[[#This Row],[Q]]<0.1, " ",IF(MOD(Inventory_List_Table341115[[#This Row],[LND USD]],1)>0.4,ROUNDUP(Inventory_List_Table341115[[#This Row],[LND USD]],0),ROUNDDOWN(Inventory_List_Table341115[[#This Row],[LND USD]],0))) | V12: =IF(Inventory_List_Table341115[[#This Row],[Q]]<0.1, " ",Inventory_List_Table341115[[#This Row],[LND RND USD]]*12) | W12: =IF(Inventory_List_Table341115[[#This Row],[Q]]<0.1, " ",Inventory_List_Table341115[[#This Row],[AQ USD]]) | X12: =IF(Inventory_List_Table341115[[#This Row],[Q]]<0.1, " ",SUBSTITUTE(SUBSTITUTE(SUBSTITUTE(SUBSTITUTE(SUBSTITUTE(SUBSTITUTE(SUBSTITUTE(SUBSTITUTE(SUBSTITUTE(SUBSTITUTE(Inventory_List_Table341115[[#This Row],[AQ RND USD]], "1", "M"), "2", "O"), "3", "X"), "4", "H"), "5", "E"), "6", "L"), "7", "F"), "8", "A"), "9", "N"), "0", "D")) | Y12: =IF(Inventory_List_Table341115[[#This Row],[Q]]<0.1, " ",SUBSTITUTE(SUBSTITUTE(SUBSTITUTE(SUBSTITUTE(SUBSTITUTE(SUBSTITUTE(SUBSTITUTE(SUBSTITUTE(SUBSTITUTE(SUBSTITUTE(Inventory_List_Table341115[[#This Row],[LND RND USD]], "1", "M"), "2", "O"), "3", "X"), "4", "H"), "5", "E"), "6", "L"), "7", "F"), "8", "A"), "9", "N"), "0", "D")) | Z12: =IF(Inventory_List_Table341115[[#This Row],[Q]]<0.1, " ",Inventory_List_Table341115[[#This Row],[H CM]]*Inventory_List_Table341115[[#This Row],[D CM ]]*4+Inventory_List_Table341115[[#This Row],[W CM]]*Inventory_List_Table341115[[#This Row],[D CM ]]/10000) | AA12: =IF(Inventory_List_Table341115[[#This Row],[Q]]<0.1, " ",Inventory_List_Table341115[[#This Row],[PRICE]]/Z12*10000)
A13: 11 | F13: =IF(Inventory_List_Table341115[[#This Row],[Q]]<0.1, " ",$A$1&$D$1&Inventory_List_Table341115[[#This Row],['#]]&Inventory_List_Table341115[[#This Row],[LC]]) | M13: =IF(Inventory_List_Table341115[[#This Row],[Q]]<0.1, " ", Inventory_List_Table341115[[#This Row],[Q]]*Inventory_List_Table341115[[#This Row],[PRICE]]) | N13: =IF(Inventory_List_Table341115[[#This Row],[Q]]<0.1, " ", Inventory_List_Table341115[[#This Row],[KG]]*2.20462) | O13: =IF(Inventory_List_Table341115[[#This Row],[Q]]<0.1, " ",Inventory_List_Table341115[[#This Row],[H CM]]/2.54) | P13: =IF(Inventory_List_Table341115[[#This Row],[Q]]<0.1, " ",Inventory_List_Table341115[[#This Row],[W CM]]/2.54) | Q13: =IF(Inventory_List_Table341115[[#This Row],[Q]]<0.1, " ",Inventory_List_Table341115[[#This Row],[D CM ]]/2.54) | R13: =IF(Inventory_List_Table341115[[#This Row],[Q]]<0.1, " ",Inventory_List_Table341115[[#This Row],[PRICE]]/$L$1) | S13: =IF(Inventory_List_Table341115[[#This Row],[Q]]<0.1, " ",IF(MOD(Inventory_List_Table341115[[#This Row],[AQ USD]],1)>0.4,ROUNDUP(Inventory_List_Table341115[[#This Row],[AQ USD]],0),ROUNDDOWN(Inventory_List_Table341115[[#This Row],[AQ USD]],0))) | T13: =IF(Inventory_List_Table341115[[#This Row],[Q]]<0.1, " ",Inventory_List_Table341115[[#This Row],[AQ RND USD]]*1.4) | U13: =IF(Inventory_List_Table341115[[#This Row],[Q]]<0.1, " ",IF(MOD(Inventory_List_Table341115[[#This Row],[LND USD]],1)>0.4,ROUNDUP(Inventory_List_Table341115[[#This Row],[LND USD]],0),ROUNDDOWN(Inventory_List_Table341115[[#This Row],[LND USD]],0))) | V13: =IF(Inventory_List_Table341115[[#This Row],[Q]]<0.1, " ",Inventory_List_Table341115[[#This Row],[LND RND USD]]*12) | W13: =IF(Inventory_List_Table341115[[#This Row],[Q]]<0.1, " ",Inventory_List_Table341115[[#This Row],[AQ USD]]) | X13: =IF(Inventory_List_Table341115[[#This Row],[Q]]<0.1, " ",SUBSTITUTE(SUBSTITUTE(SUBSTITUTE(SUBSTITUTE(SUBSTITUTE(SUBSTITUTE(SUBSTITUTE(SUBSTITUTE(SUBSTITUTE(SUBSTITUTE(Inventory_List_Table341115[[#This Row],[AQ RND USD]], "1", "M"), "2", "O"), "3", "X"), "4", "H"), "5", "E"), "6", "L"), "7", "F"), "8", "A"), "9", "N"), "0", "D")) | Y13: =IF(Inventory_List_Table341115[[#This Row],[Q]]<0.1, " ",SUBSTITUTE(SUBSTITUTE(SUBSTITUTE(SUBSTITUTE(SUBSTITUTE(SUBSTITUTE(SUBSTITUTE(SUBSTITUTE(SUBSTITUTE(SUBSTITUTE(Inventory_List_Table341115[[#This Row],[LND RND USD]], "1", "M"), "2", "O"), "3", "X"), "4", "H"), "5", "E"), "6", "L"), "7", "F"), "8", "A"), "9", "N"), "0", "D")) | Z13: =IF(Inventory_List_Table341115[[#This Row],[Q]]<0.1, " ",Inventory_List_Table341115[[#This Row],[H CM]]*Inventory_List_Table341115[[#This Row],[D CM ]]*4+Inventory_List_Table341115[[#This Row],[W CM]]*Inventory_List_Table341115[[#This Row],[D CM ]]/10000) | AA13: =IF(Inventory_List_Table341115[[#This Row],[Q]]<0.1, " ",Inventory_List_Table341115[[#This Row],[PRICE]]/Z13*10000)
A14: 12 | F14: =IF(Inventory_List_Table341115[[#This Row],[Q]]<0.1, " ",$A$1&$D$1&Inventory_List_Table341115[[#This Row],['#]]&Inventory_List_Table341115[[#This Row],[LC]]) | M14: =IF(Inventory_List_Table341115[[#This Row],[Q]]<0.1, " ", Inventory_List_Table341115[[#This Row],[Q]]*Inventory_List_Table341115[[#This Row],[PRICE]]) | N14: =IF(Inventory_List_Table341115[[#This Row],[Q]]<0.1, " ", Inventory_List_Table341115[[#This Row],[KG]]*2.20462) | O14: =IF(Inventory_List_Table341115[[#This Row],[Q]]<0.1, " ",Inventory_List_Table341115[[#This Row],[H CM]]/2.54) | P14: =IF(Inventory_List_Table341115[[#This Row],[Q]]<0.1, " ",Inventory_List_Table341115[[#This Row],[W CM]]/2.54) | Q14: =IF(Inventory_List_Table341115[[#This Row],[Q]]<0.1, " ",Inventory_List_Table341115[[#This Row],[D CM ]]/2.54) | R14: =IF(Inventory_List_Table341115[[#This Row],[Q]]<0.1, " ",Inventory_List_Table341115[[#This Row],[PRICE]]/$L$1) | S14: =IF(Inventory_List_Table341115[[#This Row],[Q]]<0.1, " ",IF(MOD(Inventory_List_Table341115[[#This Row],[AQ USD]],1)>0.4,ROUNDUP(Inventory_List_Table341115[[#This Row],[AQ USD]],0),ROUNDDOWN(Inventory_List_Table341115[[#This Row],[AQ USD]],0))) | T14: =IF(Inventory_List_Table341115[[#This Row],[Q]]<0.1, " ",Inventory_List_Table341115[[#This Row],[AQ RND USD]]*1.4) | U14: =IF(Inventory_List_Table341115[[#This Row],[Q]]<0.1, " ",IF(MOD(Inventory_List_Table341115[[#This Row],[LND USD]],1)>0.4,ROUNDUP(Inventory_List_Table341115[[#This Row],[LND USD]],0),ROUNDDOWN(Inventory_List_Table341115[[#This Row],[LND USD]],0))) | V14: =IF(Inventory_List_Table341115[[#This Row],[Q]]<0.1, " ",Inventory_List_Table341115[[#This Row],[LND RND USD]]*12) | W14: =IF(Inventory_List_Table341115[[#This Row],[Q]]<0.1, " ",Inventory_List_Table341115[[#This Row],[AQ USD]]) | X14: =IF(Inventory_List_Table341115[[#This Row],[Q]]<0.1, " ",SUBSTITUTE(SUBSTITUTE(SUBSTITUTE(SUBSTITUTE(SUBSTITUTE(SUBSTITUTE(SUBSTITUTE(SUBSTITUTE(SUBSTITUTE(SUBSTITUTE(Inventory_List_Table341115[[#This Row],[AQ RND USD]], "1", "M"), "2", "O"), "3", "X"), "4", "H"), "5", "E"), "6", "L"), "7", "F"), "8", "A"), "9", "N"), "0", "D")) | Y14: =IF(Inventory_List_Table341115[[#This Row],[Q]]<0.1, " ",SUBSTITUTE(SUBSTITUTE(SUBSTITUTE(SUBSTITUTE(SUBSTITUTE(SUBSTITUTE(SUBSTITUTE(SUBSTITUTE(SUBSTITUTE(SUBSTITUTE(Inventory_List_Table341115[[#This Row],[LND RND USD]], "1", "M"), "2", "O"), "3", "X"), "4", "H"), "5", "E"), "6", "L"), "7", "F"), "8", "A"), "9", "N"), "0", "D")) | Z14: =IF(Inventory_List_Table341115[[#This Row],[Q]]<0.1, " ",Inventory_List_Table341115[[#This Row],[H CM]]*Inventory_List_Table341115[[#This Row],[D CM ]]*4+Inventory_List_Table341115[[#This Row],[W CM]]*Inventory_List_Table341115[[#This Row],[D CM ]]/10000) | AA14: =IF(Inventory_List_Table341115[[#This Row],[Q]]<0.1, " ",Inventory_List_Table341115[[#This Row],[PRICE]]/Z14*10000)
... A102: 100 | F102: =IF(Inventory_List_Table341115[[#This Row],[Q]]<0.1, " ",$A$1&$D$1&Inventory_List_Table341115[[#This Row],['#]]&Inventory_List_Table341115[[#This Row],[LC]]) | M102: =IF(Inventory_List_Table341115[[#This Row],[Q]]<0.1, " ", Inventory_List_Table341115[[#This Row],[Q]]*Inventory_List_Table341115[[#This Row],[PRICE]]) | N102: =IF(Inventory_List_Table341115[[#This Row],[Q]]<0.1, " ", Inventory_List_Table341115[[#This Row],[KG]]*2.20462) | O102: =IF(Inventory_List_Table341115[[#This Row],[Q]]<0.1, " ",Inventory_List_Table341115[[#This Row],[H CM]]/2.54) | P102: =IF(Inventory_List_Table341115[[#This Row],[Q]]<0.1, " ",Inventory_List_Table341115[[#This Row],[W CM]]/2.54) | Q102: =IF(Inventory_List_Table341115[[#This Row],[Q]]<0.1, " ",Inventory_List_Table341115[[#This Row],[D CM ]]/2.54) | R102: =IF(Inventory_List_Table341115[[#This Row],[Q]]<0.1, " ",Inventory_List_Table341115[[#This Row],[PRICE]]/$L$1) | S102: =IF(Inventory_List_Table341115[[#This Row],[Q]]<0.1, " ",IF(MOD(Inventory_List_Table341115[[#This Row],[AQ USD]],1)>0.4,ROUNDUP(Inventory_List_Table341115[[#This Row],[AQ USD]],0),ROUNDDOWN(Inventory_List_Table341115[[#This Row],[AQ USD]],0))) | T102: =IF(Inventory_List_Table341115[[#This Row],[Q]]<0.1, " ",Inventory_List_Table341115[[#This Row],[AQ RND USD]]*1.4) | U102: =IF(Inventory_List_Table341115[[#This Row],[Q]]<0.1, " ",IF(MOD(Inventory_List_Table341115[[#This Row],[LND USD]],1)>0.4,ROUNDUP(Inventory_List_Table341115[[#This Row],[LND USD]],0),ROUNDDOWN(Inventory_List_Table341115[[#This Row],[LND USD]],0))) | V102: =IF(Inventory_List_Table341115[[#This Row],[Q]]<0.1, " ",Inventory_List_Table341115[[#This Row],[LND RND USD]]*12) | W102: =IF(Inventory_List_Table341115[[#This Row],[Q]]<0.1, " ",Inventory_List_Table341115[[#This Row],[AQ USD]]) | X102: =IF(Inventory_List_Table341115[[#This Row],[Q]]<0.1, " ",SUBSTITUTE(SUBSTITUTE(SUBSTITUTE(SUBSTITUTE(SUBSTITUTE(SUBSTITUTE(SUBSTITUTE(SUBSTITUTE(SUBSTITUTE(SUBSTITUTE(Inventory_List_Table341115[[#This Row],[AQ RND USD]], "1", "M"), "2", "O"), "3", "X"), "4", "H"), "5", "E"), "6", "L"), "7", "F"), "8", "A"), "9", "N"), "0", "D")) | Y102: =IF(Inventory_List_Table341115[[#This Row],[Q]]<0.1, " ",SUBSTITUTE(SUBSTITUTE(SUBSTITUTE(SUBSTITUTE(SUBSTITUTE(SUBSTITUTE(SUBSTITUTE(SUBSTITUTE(SUBSTITUTE(SUBSTITUTE(Inventory_List_Table341115[[#This Row],[LND RND USD]], "1", "M"), "2", "O"), "3", "X"), "4", "H"), "5", "E"), "6", "L"), "7", "F"), "8", "A"), "9", "N"), "0", "D")) | Z102: =IF(Inventory_List_Table341115[[#This Row],[Q]]<0.1, " ",Inventory_List_Table341115[[#This Row],[H CM]]*Inventory_List_Table341115[[#This Row],[D CM ]]*4+Inventory_List_Table341115[[#This Row],[W CM]]*Inventory_List_Table341115[[#This Row],[D CM ]]/10000) | AA102: =IF(Inventory_List_Table341115[[#This Row],[Q]]<0.1, " ",Inventory_List_Table341115[[#This Row],[PRICE]]/Z102*10000)

Sheet EM
A1: EM | B1: EMMANUEL | C1: Book # | D1: 326 | K1: Rate | L1: 18 | M1: =SUM(Inventory_List_Table34111510[TOTAL PESOS]) -> 0 | W1: =SUM(Inventory_List_Table34111510[TOTAL USD]) -> 0 | AA1: =IF(G3>0.1, AVERAGE(Inventory_List_Table34111510[NOTES]), " ")
