Workbook
Name Categories: OFFSET('[1]Admin & Settings'!$C$10,1,,COUNTA('[1]Admin & Settings'!$C$10:$C$33)-1,1)
Name Categories: OFFSET('[1]Admin & Settings'!$C$10,1,,COUNTA('[1]Admin & Settings'!$C$10:$C$33)-1,1)
Name Categories: OFFSET('[1]Admin & Settings'!$C$10,1,,COUNTA('[1]Admin & Settings'!$C$10:$C$33)-1,1)
Name Categories: OFFSET('[1]Admin & Settings'!$C$10,1,,COUNTA('[1]Admin & Settings'!$C$10:$C$33)-1,1)
Name Categories: OFFSET('[2]Admin & Settings'!$C$10,1,,COUNTA('[2]Admin & Settings'!$C$10:$C$33)-1,1)
Name Months: [3]Expenses!#REF!
Name Status: [4]TE!$AB$4:$AB$6
Name Status: [4]TE!$AB$4:$AB$6
Name Status: [4]TE!$AB$4:$AB$6
Name Status: [4]TE!$AB$4:$AB$6
Name Status: [5]TE!$AB$4:$AB$6
Name Status: [5]TE!$AB$4:$AB$6
Name Status: [6]TE!$AB$4:$AB$6
Name Status: [5]TE!$AB$4:$AB$6
Name Status: [6]TE!$AB$4:$AB$6
Name Status: TE!#REF!
Name valHighlight: IFERROR(IF(AM!#REF!="Yes", TRUE, FALSE),FALSE)
Name valHighlight: IFERROR(IF(AN!#REF!="Yes", TRUE, FALSE),FALSE)
Name valHighlight: IFERROR(IF(BT!#REF!="Yes", TRUE, FALSE),FALSE)
Name valHighlight: IFERROR(IF(CP!#REF!="Yes", TRUE, FALSE),FALSE)
Name valHighlight: IFERROR(IF(DH!#REF!="Yes", TRUE, FALSE),FALSE)
Name valHighlight: IFERROR(IF(EM!#REF!="Yes", TRUE, FALSE),FALSE)
Name valHighlight: IFERROR(IF(ET!#REF!="Yes", TRUE, FALSE),FALSE)
Name valHighlight: IFERROR(IF(FR!#REF!="Yes", TRUE, FALSE),FALSE)
Name valHighlight: IFERROR(IF(GE!#REF!="Yes", TRUE, FALSE),FALSE)
Name valHighlight: IFERROR(IF(GS!#REF!="Yes", TRUE, FALSE),FALSE)
Name valHighlight: IFERROR(IF(JM!#REF!="Yes", TRUE, FALSE),FALSE)
Name valHighlight: IFERROR(IF(ML!#REF!="Yes", TRUE, FALSE),FALSE)
Name valHighlight: IFERROR(IF(RF!#REF!="Yes", TRUE, FALSE),FALSE)
Name valHighlight: IFERROR(IF(TE!#REF!="Yes", TRUE, FALSE),FALSE)
Name valHighlight: IFERROR(IF(#REF!="Yes", TRUE, FALSE),FALSE)

Sheet -vPayment
A1: 825 | B1: v0128 | E1: DH | F1: =F4-(SUM(Table7[[#All],[PAYMENT DH]])) -> -11037.28 | G1: EM | H1: =H4-(SUM(Table7[[#All],[PAYMENT EM]])) -> 325420 | I1: FR | J1: =J4-SUM(I5:I29) -> -9284.5 | K1: TE | L1: =L4-SUM(K5:K29) -> 160533.5 | M1: GE | N1: =N4-SUM(M5:M29) -> 72256.5 | O1: GS | P1: =P4-SUM(O5:O29) -> 5115 | Q1: BT | R1: =R4-SUM(Q5:Q29) -> 17400 | S1: JM | T1: =T4-SUM(Table7[PAYMENT JM]) -> 22000 | U1: ML | V1: =V4-SUM(Table7[PAYMENT ML]) -> 192482 | W1: ET | X1: =X4-SUM(Table7[PAYMENT ET]) -> 119315 | Y1: AM | Z1: =Z4-SUM(Y4:Y29) -> 114240 | AA1: RF | AB1: =AB4-SUM(AA4:AA29) -> 77185 | AC1: CP | AD1: =AD4-SUM(AC4:AC29) -> 30000 | AE1: AN | AF1: =AF4-SUM(AE4:AE29) -> 12000
A2: USD MXN RATE | B2: TOTAL AQ MXN | C2: VENDOR PAYMENT TRACKING | E2: DELFINO HERNANDEZ | G2: EMMANUEL DE LOS SANTOS | I2: FOUNTAIN ROCK | K2: TELLEZ GALERY | M2: GERARDO DE GANTE | O2: GIFT SHOP | Q2: BERNARDO TELLEZ | S2: JOSE MEZA | U2: MARIA LUISA AND JAIR | W2: LALO TELLEZ | Y2: ALEJANDRO AND FANY MEZA | AA2: ALEJANDRO AND FANY MEZA | AC2: CANTERA PUEBLA | AE2: ANGEL CABRERA
A3: 18 | B3: =RF!K2+AM!K2+JM!K2+AN!K2+CP!K2+ML!K2+EM!K2+DH!K2+FR!K2+TE!K2+GE!K2+GS!K2+BT!K2+ET!K2 -> 3052411.3 | E3: PAYMENT DH | F3: BALANCE DH | G3: PAYMENT EM | H3: BALANCE EM | I3: PAYMEN FR | J3: BALANCE FR | K3: PAYMENT TE | L3: BALANCE TE | M3: PAYMENT GE | N3: BALANCE GE | O3: PAYMENT LH2 | P3: BALANCE GS3 | Q3: PAYMENTBT | R3: BALANCEBT | S3: PAYMENT JM | T3: BALANCE JM | U3: PAYMENT ML | V3: BALANCE ML | W3: PAYMENT ET | X3: BALANCE MT | Y3: PAYMENT AM | Z3: BALANCE AM | AA3: PAYMENT AM | AB3: BALANCE AM | AC3: PAYMENT CP | AD3: BALANCE CP | AE3: PAYMENT CP | AF3: BALANCE CP
A4: SHIPPING RECORD | C4: TYPE | D4: FROM VENDOR SHEET | E4: FROM DH | F4: =DH!K2 -> 348472.8 | G4: FROM EM | H4: =EM!K2 -> 779315.5 | J4: =[5]FR!K2 -> 135715.5 | K4: FROM TE | L4: =[5]TE!S1 -> 452094 | M4: FROM GE | N4: =[5]GE!K2 -> 150221.5 | O4: FROM GS | P4: =[5]GS!S2 -> 61290 | Q4: FROM BT | R4: =[5]BT!K2 -> 104500 | S4: FROM JM | T4: =JM!K2 -> 476680 | V4: =ML!K2 -> 192482 | X4: =ET!K2 -> 119315 | Z4: =AM!K2 -> 114240 | AB4: =RF!K2 -> 77185 | AD4: =CP!K2 -> 30000 | AF4: =AN!K2 -> 12000
A5: TRK1 | B5: 666790 | C5: DIRECT WIRE | D5: 07/30/2025 | F5: =F4-Table7[[#This Row],[PAYMENT DH]] -> 348472.8 | H5: =H4-Table7[[#This Row],[PAYMENT EM]] -> 779315.5 | J5: =J4-Table7[[#This Row],[PAYMEN FR]] -> 135715.5 | K5: 237760.5 | L5: =L4-Table7[[#This Row],[PAYMENT TE]] -> 214333.5 | N5: =N4-Table7[[#This Row],[PAYMENT GE]] -> 150221.5 | P5: =P4-Table7[[#This Row],[PAYMENT LH2]] -> 61290 | R5: =R4-Table7[[#This Row],[PAYMENTBT]] -> 104500 | T5: =T4-S5 -> 476680 | V5: =V4-Table7[[#This Row],[PAYMENT ML]] -> 192482 | X5: =X4-W5 -> 119315 | Z5: =Z4-Y5 -> 114240 | AB5: =AB4-AA5 -> 77185 | AD5: =AD4-AC5 -> 30000 | AF5: =AF4-AE5 -> 12000
A6: TRK2 | B6: 493962.54 | C6: CASH | D6: 07/31/2025 | F6: =F5-Table7[[#This Row],[PAYMENT DH]] -> 348472.8 | H6: =H5-Table7[[#This Row],[PAYMENT EM]] -> 779315.5 | J6: =J5-Table7[[#This Row],[PAYMEN FR]] -> 135715.5 | L6: =L5-Table7[[#This Row],[PAYMENT TE]] -> 214333.5 | N6: =N5-Table7[[#This Row],[PAYMENT GE]] -> 150221.5 | O6: 18000 | P6: =P5-Table7[[#This Row],[PAYMENT LH2]] -> 43290 | R6: =R5-Table7[[#This Row],[PAYMENTBT]] -> 104500 | T6: =T5-S6 -> 476680 | V6: =V5-Table7[[#This Row],[PAYMENT ML]] -> 192482 | X6: =X5-W6 -> 119315 | Z6: =Z5-Y6 -> 114240 | AB6: =AB5-AA6 -> 77185 | AD6: =AD5-AC6 -> 30000 | AF6: =AF5-AE6 -> 12000
A7: TRK3 | B7: 253320.36 | C7: CASH | D7: 07/31/2025 | F7: =F6-Table7[[#This Row],[PAYMENT DH]] -> 348472.8 | H7: =H6-Table7[[#This Row],[PAYMENT EM]] -> 779315.5 | J7: =J6-Table7[[#This Row],[PAYMEN FR]] -> 135715.5 | L7: =L6-Table7[[#This Row],[PAYMENT TE]] -> 214333.5 | N7: =N6-Table7[[#This Row],[PAYMENT GE]] -> 150221.5 | O7: 27000 | P7: =P6-Table7[[#This Row],[PAYMENT LH2]] -> 16290 | R7: =R6-Table7[[#This Row],[PAYMENTBT]] -> 104500 | T7: =T6-S7 -> 476680 | V7: =V6-Table7[[#This Row],[PAYMENT ML]] -> 192482 | X7: =X6-W7 -> 119315 | Z7: =Z6-Y7 -> 114240 | AB7: =AB6-AA7 -> 77185 | AD7: =AD6-AC7 -> 30000 | AF7: =AF6-AE7 -> 12000
A8: ='-TRK4'!A2 -> TRK4 | B8: =RF!K2+AM!K2+EM!K1+JM!K1+ML!K1+TE!K1+GE!K1+BT!K1+ET!K2 -> 1424429.5 | C8: CASH W | D8: 6/7/25 | E8: 100000 | F8: =F7-Table7[[#This Row],[PAYMENT DH]] -> 248472.8 | H8: =H7-Table7[[#This Row],[PAYMENT EM]] -> 779315.5 | J8: =J7-Table7[[#This Row],[PAYMEN FR]] -> 135715.5 | L8: =L7-Table7[[#This Row],[PAYMENT TE]] -> 214333.5 | N8: =N7-Table7[[#This Row],[PAYMENT GE]] -> 150221.5 | P8: =P7-Table7[[#This Row],[PAYMENT LH2]] -> 16290 | R8: =R7-Table7[[#This Row],[PAYMENTBT]] -> 104500 | T8: =T7-S8 -> 476680 | V8: =V7-Table7[[#This Row],[PAYMENT ML]] -> 192482 | X8: =X7-W8 -> 119315 | Z8: =Z7-Y8 -> 114240 | AB8: =AB7-AA8 -> 77185 | AD8: =AD7-AC8 -> 30000 | AF8: =AF7-AE8 -> 12000
A9: T SHIPPED | B9: =SUM(B5:B8) -> 2838502.4 | C9: IVA 10641.6 | D9: 8/13/25 | E9: 66510.08 | F9: =F8-Table7[[#This Row],[PAYMENT DH]] -> 181962.72 | H9: =H8-Table7[[#This Row],[PAYMENT EM]] -> 779315.5 | J9: =J8-Table7[[#This Row],[PAYMEN FR]] -> 135715.5 | L9: =L8-Table7[[#This Row],[PAYMENT TE]] -> 214333.5 | N9: =N8-Table7[[#This Row],[PAYMENT GE]] -> 150221.5 | P9: =P8-Table7[[#This Row],[PAYMENT LH2]] -> 16290 | R9: =R8-Table7[[#This Row],[PAYMENTBT]] -> 104500 | T9: =T8-S9 -> 476680 | V9: =V8-Table7[[#This Row],[PAYMENT ML]] -> 192482 | X9: =X8-W9 -> 119315 | Z9: =Z8-Y9 -> 114240 | AB9: =AB8-AA9 -> 77185 | AD9: =AD8-AC9 -> 30000 | AF9: =AF8-AE9 -> 12000
A10: IN WAREHOUSE | B10: =B3-B9 -> 213908.9 | C10: CASH | D10: 5/30/25 | F10: =F9-Table7[[#This Row],[PAYMENT DH]] -> 181962.72 | H10: =H9-Table7[[#This Row],[PAYMENT EM]] -> 779315.5 | J10: =J9-Table7[[#This Row],[PAYMEN FR]] -> 135715.5 | L10: =L9-Table7[[#This Row],[PAYMENT TE]] -> 214333.5 | N10: =N9-Table7[[#This Row],[PAYMENT GE]] -> 150221.5 | P10: =P9-Table7[[#This Row],[PAYMENT LH2]] -> 16290 | Q10: 60100 | R10: =R9-Table7[[#This Row],[PAYMENTBT]] -> 44400 | T10: =T9-S10 -> 476680 | V10: =V9-Table7[[#This Row],[PAYMENT ML]] -> 192482 | X10: =X9-W10 -> 119315 | Z10: =Z9-Y10 -> 114240 | AB10: =AB9-AA10 -> 77185 | AD10: =AD9-AC10 -> 30000 | AF10: =AF9-AE10 -> 12000
C11: CASH | D11: 6/18/25 | F11: =F10-Table7[[#This Row],[PAYMENT DH]] -> 181962.72 | H11: =H10-Table7[[#This Row],[PAYMENT EM]] -> 779315.5 | I11: 120000 | J11: =J10-Table7[[#This Row],[PAYMEN FR]] -> 15715.5 | L11: =L10-Table7[[#This Row],[PAYMENT TE]] -> 214333.5 | N11: =N10-Table7[[#This Row],[PAYMENT GE]] -> 150221.5 | P11: =P10-Table7[[#This Row],[PAYMENT LH2]] -> 16290 | R11: =R10-Table7[[#This Row],[PAYMENTBT]] -> 44400 | T11: =T10-S11 -> 476680 | V11: =V10-Table7[[#This Row],[PAYMENT ML]] -> 192482 | X11: =X10-W11 -> 119315 | Z11: =Z10-Y11 -> 114240 | AB11: =AB10-AA11 -> 77185 | AD11: =AD10-AC11 -> 30000 | AF11: =AF10-AE11 -> 12000
C12: CASH | D12: 8/12/25 | F12: =F11-Table7[[#This Row],[PAYMENT DH]] -> 181962.72 | H12: =H11-Table7[[#This Row],[PAYMENT EM]] -> 779315.5 | I12: 25000 | J12: =J11-Table7[[#This Row],[PAYMEN FR]] -> -9284.5 | L12: =L11-Table7[[#This Row],[PAYMENT TE]] -> 214333.5 | N12: =N11-Table7[[#This Row],[PAYMENT GE]] -> 150221.5 | P12: =P11-Table7[[#This Row],[PAYMENT LH2]] -> 16290 | R12: =R11-Table7[[#This Row],[PAYMENTBT]] -> 44400 | T12: =T11-S12 -> 476680 | V12: =V11-Table7[[#This Row],[PAYMENT ML]] -> 192482 | X12: =X11-W12 -> 119315 | Z12: =Z11-Y12 -> 114240 | AB12: =AB11-AA12 -> 77185 | AD12: =AD11-AC12 -> 30000 | AF12: =AF11-AE12 -> 12000
C13: CASH CHAD | D13: 06/07/2025 | F13: =F12-Table7[[#This Row],[PAYMENT DH]] -> 181962.72 | H13: =H12-Table7[[#This Row],[PAYMENT EM]] -> 779315.5 | J13: =J12-Table7[[#This Row],[PAYMEN FR]] -> -9284.5 | L13: =L12-Table7[[#This Row],[PAYMENT TE]] -> 214333.5 | M13: 30000 | N13: =N12-Table7[[#This Row],[PAYMENT GE]] -> 120221.5 | P13: =P12-Table7[[#This Row],[PAYMENT LH2]] -> 16290 | R13: =R12-Table7[[#This Row],[PAYMENTBT]] -> 44400 | T13: =T12-S13 -> 476680 | V13: =V12-Table7[[#This Row],[PAYMENT ML]] -> 192482 | X13: =X12-W13 -> 119315 | Z13: =Z12-Y13 -> 114240 | AB13: =AB12-AA13 -> 77185 | AD13: =AD12-AC13 -> 30000 | AF13: =AF12-AE13 -> 12000
C14: IVA 7674.40 | D14: 8/23/2025 | F14: =F13-Table7[[#This Row],[PAYMENT DH]] -> 181962.72 | H14: =H13-Table7[[#This Row],[PAYMENT EM]] -> 779315.5 | J14: =J13-Table7[[#This Row],[PAYMEN FR]] -> -9284.5 | L14: =L13-Table7[[#This Row],[PAYMENT TE]] -> 214333.5 | M14: 47965 | N14: =N13-Table7[[#This Row],[PAYMENT GE]] -> 72256.5 | P14: =P13-Table7[[#This Row],[PAYMENT LH2]] -> 16290 | R14: =R13-Table7[[#This Row],[PAYMENTBT]] -> 44400 | T14: =T13-S14 -> 476680 | V14: =V13-Table7[[#This Row],[PAYMENT ML]] -> 192482 | X14: =X13-W14 -> 119315 | Z14: =Z13-Y14 -> 114240 | AB14: =AB13-AA14 -> 77185 | AD14: =AD13-AC14 -> 30000 | AF14: =AF13-AE14 -> 12000
C15: CASH | D15: 8/31/2025 | F15: =F14-Table7[[#This Row],[PAYMENT DH]] -> 181962.72 | H15: =H14-Table7[[#This Row],[PAYMENT EM]] -> 779315.5 | J15: =J14-Table7[[#This Row],[PAYMEN FR]] -> -9284.5 | L15: =L14-Table7[[#This Row],[PAYMENT TE]] -> 214333.5 | N15: =N14-Table7[[#This Row],[PAYMENT GE]] -> 72256.5 | O15: 11175 | P15: =P14-Table7[[#This Row],[PAYMENT LH2]] -> 5115 | R15: =R14-Table7[[#This Row],[PAYMENTBT]] -> 44400 | T15: =T14-S15 -> 476680 | V15: =V14-Table7[[#This Row],[PAYMENT ML]] -> 192482 | X15: =X14-W15 -> 119315 | Z15: =Z14-Y15 -> 114240 | AB15: =AB14-AA15 -> 77185 | AD15: =AD14-AC15 -> 30000 | AF15: =AF14-AE15 -> 12000
C16: IVA 51814 | D16: 8/25/2025 | F16: =F15-Table7[[#This Row],[PAYMENT DH]] -> 181962.72 | G16: 323838.5 | H16: =H15-Table7[[#This Row],[PAYMENT EM]] -> 455477 | J16: =J15-Table7[[#This Row],[PAYMEN FR]] -> -9284.5 | L16: =L15-Table7[[#This Row],[PAYMENT TE]] -> 214333.5 | N16: =N15-Table7[[#This Row],[PAYMENT GE]] -> 72256.5 | P16: =P15-Table7[[#This Row],[PAYMENT LH2]] -> 5115 | R16: =R15-Table7[[#This Row],[PAYMENTBT]] -> 44400 | T16: =T15-S16 -> 476680 | V16: =V15-Table7[[#This Row],[PAYMENT ML]] -> 192482 | X16: =X15-W16 -> 119315 | Z16: =Z15-Y16 -> 114240 | AB16: =AB15-AA16 -> 77185 | AD16: =AD15-AC16 -> 30000 | AF16: =AF15-AE16 -> 12000
C17: CASH | D17: 9/1/2025 | F17: =F16-Table7[[#This Row],[PAYMENT DH]] -> 181962.72 | H17: =H16-Table7[[#This Row],[PAYMENT EM]] -> 455477 | J17: =J16-Table7[[#This Row],[PAYMEN FR]] -> -9284.5 | L17: =L16-Table7[[#This Row],[PAYMENT TE]] -> 214333.5 | N17: =N16-Table7[[#This Row],[PAYMENT GE]] -> 72256.5 | P17: =P16-Table7[[#This Row],[PAYMENT LH2]] -> 5115 | Q17: 27000 | R17: =R16-Table7[[#This Row],[PAYMENTBT]] -> 17400 | T17: =T16-S17 -> 476680 | V17: =V16-Table7[[#This Row],[PAYMENT ML]] -> 192482 | X17: =X16-W17 -> 119315 | Z17: =Z16-Y17 -> 114240 | AB17: =AB16-AA17 -> 77185 | AD17: =AD16-AC17 -> 30000 | AF17: =AF16-AE17 -> 12000
C18: cash | D18: 9/5/25 | F18: =F17-Table7[[#This Row],[PAYMENT DH]] -> 181962.72 | H18: =H17-Table7[[#This Row],[PAYMENT EM]] -> 455477 | J18: =J17-Table7[[#This Row],[PAYMEN FR]] -> -9284.5 | K18: 23000 | L18: =L17-Table7[[#This Row],[PAYMENT TE]] -> 191333.5 | N18: =N17-Table7[[#This Row],[PAYMENT GE]] -> 72256.5 | P18: =P17-Table7[[#This Row],[PAYMENT LH2]] -> 5115 | R18: =R17-Table7[[#This Row],[PAYMENTBT]] -> 17400 | T18: =T17-S18 -> 476680 | V18: =V17-Table7[[#This Row],[PAYMENT ML]] -> 192482 | X18: =X17-W18 -> 119315 | Z18: =Z17-Y18 -> 114240 | AB18: =AB17-AA18 -> 77185 | AD18: =AD17-AC18 -> 30000 | AF18: =AF17-AE18 -> 12000
C19: IVA20809.12 | D19: 11/9/25 | F19: =F18-Table7[[#This Row],[PAYMENT DH]] -> 181962.72 | G19: 130057 | H19: =H18-Table7[[#This Row],[PAYMENT EM]] -> 325420 | J19: =J18-Table7[[#This Row],[PAYMEN FR]] -> -9284.5 | L19: =L18-Table7[[#This Row],[PAYMENT TE]] -> 191333.5 | N19: =N18-Table7[[#This Row],[PAYMENT GE]] -> 72256.5 | P19: =P18-Table7[[#This Row],[PAYMENT LH2]] -> 5115 | R19: =R18-Table7[[#This Row],[PAYMENTBT]] -> 17400 | T19: =T18-S19 -> 476680 | V19: =V18-Table7[[#This Row],[PAYMENT ML]] -> 192482 | X19: =X18-W19 -> 119315 | Z19: =Z18-Y19 -> 114240 | AB19: =AB18-AA19 -> 77185 | AD19: =AD18-AC19 -> 30000 | AF19: =AF18-AE19 -> 12000
C20: CASH | D20: 10/30/25 | F20: =F19-Table7[[#This Row],[PAYMENT DH]] -> 181962.72 | H20: =H19-Table7[[#This Row],[PAYMENT EM]] -> 325420 | J20: =J19-Table7[[#This Row],[PAYMEN FR]] -> -9284.5 | K20: 30800 | L20: =L19-Table7[[#This Row],[PAYMENT TE]] -> 160533.5 | N20: =N19-Table7[[#This Row],[PAYMENT GE]] -> 72256.5 | P20: =P19-Table7[[#This Row],[PAYMENT LH2]] -> 5115 | R20: =R19-Table7[[#This Row],[PAYMENTBT]] -> 17400 | T20: =T19-S20 -> 476680 | V20: =V19-Table7[[#This Row],[PAYMENT ML]] -> 192482 | X20: =X19-W20 -> 119315 | Z20: =Z19-Y20 -> 114240 | AB20: =AB19-AA20 -> 77185 | AD20: =AD19-AC20 -> 30000 | AF20: =AF19-AE20 -> 12000
C21: IVA 14880 | D21: 9/18/25 | E21: 93000 | F21: =F20-Table7[[#This Row],[PAYMENT DH]] -> 88962.72 | H21: =H20-Table7[[#This Row],[PAYMENT EM]] -> 325420 | J21: =J20-Table7[[#This Row],[PAYMEN FR]] -> -9284.5 | L21: =L20-Table7[[#This Row],[PAYMENT TE]] -> 160533.5 | N21: =N20-Table7[[#This Row],[PAYMENT GE]] -> 72256.5 | P21: =P20-Table7[[#This Row],[PAYMENT LH2]] -> 5115 | R21: =R20-Table7[[#This Row],[PAYMENTBT]] -> 17400 | T21: =T20-S21 -> 476680 | V21: =V20-Table7[[#This Row],[PAYMENT ML]] -> 192482 | X21: =X20-W21 -> 119315 | Z21: =Z20-Y21 -> 114240 | AB21: =AB20-AA21 -> 77185 | AD21: =AD20-AC21 -> 30000 | AF21: =AF20-AE21 -> 12000
C22: CASH | D22: 12/10/25 | E22: 75000 | F22: =F21-Table7[[#This Row],[PAYMENT DH]] -> 13962.72 | H22: =H21-Table7[[#This Row],[PAYMENT EM]] -> 325420 | J22: =J21-Table7[[#This Row],[PAYMEN FR]] -> -9284.5 | L22: =L21-Table7[[#This Row],[PAYMENT TE]] -> 160533.5 | N22: =N21-Table7[[#This Row],[PAYMENT GE]] -> 72256.5 | P22: =P21-Table7[[#This Row],[PAYMENT LH2]] -> 5115 | R22: =R21-Table7[[#This Row],[PAYMENTBT]] -> 17400 | T22: =T21-S22 -> 476680 | V22: =V21-Table7[[#This Row],[PAYMENT ML]] -> 192482 | X22: =X21-W22 -> 119315 | Z22: =Z21-Y22 -> 114240 | AB22: =AB21-AA22 -> 77185 | AD22: =AD21-AC22 -> 30000 | AF22: =AF21-AE22 -> 12000
C23: CASH | E23: 25000 | F23: =F22-Table7[[#This Row],[PAYMENT DH]] -> -11037.28 | H23: =H22-Table7[[#This Row],[PAYMENT EM]] -> 325420 | J23: =J22-Table7[[#This Row],[PAYMEN FR]] -> -9284.5 | L23: =L22-Table7[[#This Row],[PAYMENT TE]] -> 160533.5 | N23: =N22-Table7[[#This Row],[PAYMENT GE]] -> 72256.5 | P23: =P22-Table7[[#This Row],[PAYMENT LH2]] -> 5115 | R23: =R22-Table7[[#This Row],[PAYMENTBT]] -> 17400 | T23: =T22-S23 -> 476680 | V23: =V22-Table7[[#This Row],[PAYMENT ML]] -> 192482 | X23: =X22-W23 -> 119315 | Z23: =Z22-Y23 -> 114240 | AB23: =AB22-AA23 -> 77185 | AD23: =AD22-AC23 -> 30000 | AF23: =AF22-AE23 -> 12000
C24: DIRECT WIRE | D24: 10/28/2025 | F24: =F23-Table7[[#This Row],[PAYMENT DH]] -> -11037.28 | H24: =H23-Table7[[#This Row],[PAYMENT EM]] -> 325420 | J24: =J23-Table7[[#This Row],[PAYMEN FR]] -> -9284.5 | L24: =L23-Table7[[#This Row],[PAYMENT TE]] -> 160533.5 | N24: =N23-Table7[[#This Row],[PAYMENT GE]] -> 72256.5 | P24: =P23-Table7[[#This Row],[PAYMENT LH2]] -> 5115 | R24: =R23-Table7[[#This Row],[PAYMENTBT]] -> 17400 | S24: 79100 | T24: =T23-S24 -> 397580 | V24: =V23-Table7[[#This Row],[PAYMENT ML]] -> 192482 | X24: =X23-W24 -> 119315 | Z24: =Z23-Y24 -> 114240 | AB24: =AB23-AA24 -> 77185 | AD24: =AD23-AC24 -> 30000 | AF24: =AF23-AE24 -> 12000
C25: direct wire | D25: 1/22/2026 | F25: =F24-Table7[[#This Row],[PAYMENT DH]] -> -11037.28 | H25: =H24-Table7[[#This Row],[PAYMENT EM]] -> 325420 | J25: =J24-Table7[[#This Row],[PAYMEN FR]] -> -9284.5 | L25: =L24-Table7[[#This Row],[PAYMENT TE]] -> 160533.5 | N25: =N24-Table7[[#This Row],[PAYMENT GE]] -> 72256.5 | P25: =P24-Table7[[#This Row],[PAYMENT LH2]] -> 5115 | R25: =R24-Table7[[#This Row],[PAYMENTBT]] -> 17400 | S25: 375580 | T25: =T24-S25 -> 22000 | V25: =V24-Table7[[#This Row],[PAYMENT ML]] -> 192482 | X25: =X24-W25 -> 119315 | Z25: =Z24-Y25 -> 114240 | AB25: =AB24-AA25 -> 77185 | AD25: =AD24-AC25 -> 30000 | AF25: =AF24-AE25 -> 12000
F26: =F25-Table7[[#This Row],[PAYMENT DH]] -> -11037.28 | H26: =H25-Table7[[#This Row],[PAYMENT EM]] -> 325420 | J26: =J25-Table7[[#This Row],[PAYMEN FR]] -> -9284.5 | L26: =L25-Table7[[#This Row],[PAYMENT TE]] -> 160533.5 | N26: =N25-Table7[[#This Row],[PAYMENT GE]] -> 72256.5 | P26: =P25-Table7[[#This Row],[PAYMENT LH2]] -> 5115 | R26: =R25-Table7[[#This Row],[PAYMENTBT]] -> 17400 | T26: =T25-S26 -> 22000 | V26: =V25-Table7[[#This Row],[PAYMENT ML]] -> 192482 | X26: =X25-W26 -> 119315 | Z26: =Z25-Y26 -> 114240 | AB26: =AB25-AA26 -> 77185 | AD26: =AD25-AC26 -> 30000 | AF26: =AF25-AE26 -> 12000
F27: =F26-Table7[[#This Row],[PAYMENT DH]] -> -11037.28 | H27: =H26-Table7[[#This Row],[PAYMENT EM]] -> 325420 | J27: =J26-Table7[[#This Row],[PAYMEN FR]] -> -9284.5 | L27: =L26-Table7[[#This Row],[PAYMENT TE]] -> 160533.5 | N27: =N26-Table7[[#This Row],[PAYMENT GE]] -> 72256.5 | P27: =P26-Table7[[#This Row],[PAYMENT LH2]] -> 5115 | R27: =R26-Table7[[#This Row],[PAYMENTBT]] -> 17400 | T27: =T26-S27 -> 22000 | V27: =V26-Table7[[#This Row],[PAYMENT ML]] -> 192482 | X27: =X26-W27 -> 119315 | Z27: =Z26-Y27 -> 114240 | AB27: =AB26-AA27 -> 77185 | AD27: =AD26-AC27 -> 30000 | AF27: =AF26-AE27 -> 12000
F28: =F27-Table7[[#This Row],[PAYMENT DH]] -> -11037.28 | H28: =H27-Table7[[#This Row],[PAYMENT EM]] -> 325420 | J28: =J27-Table7[[#This Row],[PAYMEN FR]] -> -9284.5 | L28: =L27-Table7[[#This Row],[PAYMENT TE]] -> 160533.5 | N28: =N27-Table7[[#This Row],[PAYMENT GE]] -> 72256.5 | P28: =P27-Table7[[#This Row],[PAYMENT LH2]] -> 5115 | R28: =R27-Table7[[#This Row],[PAYMENTBT]] -> 17400 | T28: =T27-S28 -> 22000 | V28: =V27-Table7[[#This Row],[PAYMENT ML]] -> 192482 | X28: =X27-W28 -> 119315 | Z28: =Z27-Y28 -> 114240 | AB28: =AB27-AA28 -> 77185 | AD28: =AD27-AC28 -> 30000 | AF28: =AF27-AE28 -> 12000
F29: =F28-Table7[[#This Row],[PAYMENT DH]] -> -11037.28 | H29: =H28-Table7[[#This Row],[PAYMENT EM]] -> 325420 | J29: =J28-Table7[[#This Row],[PAYMEN FR]] -> -9284.5 | L29: =L28-Table7[[#This Row],[PAYMENT TE]] -> 160533.5 | N29: =N28-Table7[[#This Row],[PAYMENT GE]] -> 72256.5 | P29: =P28-Table7[[#This Row],[PAYMENT LH2]] -> 5115 | R29: =R28-Table7[[#This Row],[PAYMENTBT]] -> 17400 | T29: =T28-S29 -> 22000 | V29: =V28-Table7[[#This Row],[PAYMENT ML]] -> 192482 | X29: =X28-W29 -> 119315 | Z29: =Z28-Y29 -> 114240 | AB29: =AB28-AA29 -> 77185 | AD29: =AD28-AC29 -> 30000 | AF29: =AF28-AE29 -> 12000

Sheet -vSupplies
A1: SUPPLIES | B1: 825
A2: BALANCE | B2: =B3-B4 -> -15416
A3: TOTAL IN | B3: =SUM(Table115[[#All],[$MSN IN]]) -> 294294
A4: TOTAL OUT | B4: =SUM(Table115[TOTAL $]) -> 309710 | G4: \
A5: Date | B5: VENDOR | C5: ITEM | D5: DESCTIPTION | E5: Q | F5: $MSN IN | G5: $MXN OUT | H5: TOTAL $ | I5: $USD | J5: TOTAL USD
A6: 45945 | C6: atm | D6: withdrawal | E6: 1 | F6: 11000 | H6: =Table115[[#This Row],[Q]]*Table115[[#This Row],[$MXN OUT]] -> 0 | K6: =Table115[[#This Row],[$MSN IN]]-Table115[[#This Row],[$MXN OUT]] -> 11000
C7: atm | D7: withdrawal | E7: 1 | F7: 11000 | H7: =Table115[[#This Row],[Q]]*Table115[[#This Row],[$MXN OUT]] -> 0 | K7: =+K6+Table115[[#This Row],[$MSN IN]]-Table115[[#This Row],[$MXN OUT]] -> 22000
C8: atm | D8: withdrawal | E8: 1 | F8: 12000 | H8: =Table115[[#This Row],[Q]]*Table115[[#This Row],[$MXN OUT]] -> 0 | K8: =+K7+Table115[[#This Row],[$MSN IN]]-Table115[[#This Row],[$MXN OUT]] -> 34000
C9: atm | D9: withdrawal | E9: 1 | F9: 12000 | H9: =Table115[[#This Row],[Q]]*Table115[[#This Row],[$MXN OUT]] -> 0 | K9: =+K8+Table115[[#This Row],[$MSN IN]]-Table115[[#This Row],[$MXN OUT]] -> 46000
B10: warehouse | C10: rent | D10: september | E10: 1 | G10: 12000 | H10: =Table115[[#This Row],[Q]]*Table115[[#This Row],[$MXN OUT]] -> 12000 | K10: =+K9+Table115[[#This Row],[$MSN IN]]-Table115[[#This Row],[$MXN OUT]] -> 34000
B11: warehouse | C11: rent | D11: october | E11: 1 | G11: 12000 | H11: =Table115[[#This Row],[Q]]*Table115[[#This Row],[$MXN OUT]] -> 12000 | K11: =+K10+Table115[[#This Row],[$MSN IN]]-Table115[[#This Row],[$MXN OUT]] -> 22000
B12: personal | C12: advance | E12: 1 | G12: 15000 | H12: =Table115[[#This Row],[Q]]*Table115[[#This Row],[$MXN OUT]] -> 15000 | K12: =+K11+Table115[[#This Row],[$MSN IN]]-Table115[[#This Row],[$MXN OUT]] -> 7000
B13: house | C13: rent | D13: october | E13: 1 | G13: 7000 | H13: =Table115[[#This Row],[Q]]*Table115[[#This Row],[$MXN OUT]] -> 7000 | K13: =+K12+Table115[[#This Row],[$MSN IN]]-Table115[[#This Row],[$MXN OUT]] -> 0
A14: 45963 | C14: atm | D14: withdrawal | E14: 1 | F14: 11900 | H14: =Table115[[#This Row],[Q]]*Table115[[#This Row],[$MXN OUT]] -> 0 | K14: =+K13+Table115[[#This Row],[$MSN IN]]-Table115[[#This Row],[$MXN OUT]] -> 11900
C15: atm | D15: withdrawal | E15: 1 | F15: 11500 | H15: =Table115[[#This Row],[Q]]*Table115[[#This Row],[$MXN OUT]] -> 0 | K15: =+K14+Table115[[#This Row],[$MSN IN]]-Table115[[#This Row],[$MXN OUT]] -> 23400
C16: atm | D16: withdrawal | E16: 1 | F16: 11500 | H16: =Table115[[#This Row],[Q]]*Table115[[#This Row],[$MXN OUT]] -> 0 | K16: =+K15+Table115[[#This Row],[$MSN IN]]-Table115[[#This Row],[$MXN OUT]] -> 34900
C17: atm | D17: withdrawal | E17: 1 | F17: 11500 | H17: =Table115[[#This Row],[Q]]*Table115[[#This Row],[$MXN OUT]] -> 0 | K17: =+K16+Table115[[#This Row],[$MSN IN]]-Table115[[#This Row],[$MXN OUT]] -> 46400
C18: atm | D18: withdrawal | E18: 1 | F18: 10000 | H18: =Table115[[#This Row],[Q]]*Table115[[#This Row],[$MXN OUT]] -> 0 | K18: =+K17+Table115[[#This Row],[$MSN IN]]-Table115[[#This Row],[$MXN OUT]] -> 56400
B19: delfino | C19: fountain rock | D19: cash | E19: 1 | G19: 50000 | H19: =Table115[[#This Row],[Q]]*Table115[[#This Row],[$MXN OUT]] -> 50000 | K19: =+K18+Table115[[#This Row],[$MSN IN]]-Table115[[#This Row],[$MXN OUT]] -> 6400
B20: simona | C20: palets | D20: fountain | E20: 6 | G20: 1300 | H20: =Table115[[#This Row],[Q]]*Table115[[#This Row],[$MXN OUT]] -> 7800 | K20: =+K19+Table115[[#This Row],[$MSN IN]]-Table115[[#This Row],[$MXN OUT]] -> 5100
B21: simona | C21: palets | D21: fountain | E21: 6 | G21: 1500 | H21: =Table115[[#This Row],[Q]]*Table115[[#This Row],[$MXN OUT]] -> 9000 | K21: =+K20+Table115[[#This Row],[$MSN IN]]-Table115[[#This Row],[$MXN OUT]] -> 3600
B22: simona | C22: palets | D22: fountain | E22: 2 | G22: 850 | H22: =Table115[[#This Row],[Q]]*Table115[[#This Row],[$MXN OUT]] -> 1700 | K22: =+K21+Table115[[#This Row],[$MSN IN]]-Table115[[#This Row],[$MXN OUT]] -> 2750
B23: simona | C23: crates | D23: emmanuel | E23: 1 | G23: 3900 | H23: =Table115[[#This Row],[Q]]*Table115[[#This Row],[$MXN OUT]] -> 3900 | K23: =+K22+Table115[[#This Row],[$MSN IN]]-Table115[[#This Row],[$MXN OUT]] -> -1150
B24: simona | C24: crates | D24: emmanuel | E24: 1 | G24: 2000 | H24: =Table115[[#This Row],[Q]]*Table115[[#This Row],[$MXN OUT]] -> 2000 | K24: =+K23+Table115[[#This Row],[$MSN IN]]-Table115[[#This Row],[$MXN OUT]] -> -3150
B25: simona | C25: crates | D25: emmanuel | E25: 3 | G25: 3000 | H25: =Table115[[#This Row],[Q]]*Table115[[#This Row],[$MXN OUT]] -> 9000 | K25: =+K24+Table115[[#This Row],[$MSN IN]]-Table115[[#This Row],[$MXN OUT]] -> -6150
B26: simona | C26: crates | D26: emmanuel | E26: 1 | G26: 1600 | H26: =Table115[[#This Row],[Q]]*Table115[[#This Row],[$MXN OUT]] -> 1600 | K26: =+K25+Table115[[#This Row],[$MSN IN]]-Table115[[#This Row],[$MXN OUT]] -> -7750 | L26: =SUM(H20:H26) -> 35000
B27: angel | C27: cactus set | D27: advance 50% | E27: 1 | G27: 6000 | H27: =Table115[[#This Row],[Q]]*Table115[[#This Row],[$MXN OUT]] -> 6000 | K27: =+K26+Table115[[#This Row],[$MSN IN]]-Table115[[#This Row],[$MXN OUT]] -> -13750
B28: forklift | C28: service | E28: 1 | G28: 2600 | H28: =Table115[[#This Row],[Q]]*Table115[[#This Row],[$MXN OUT]] -> 2600 | K28: =+K27+Table115[[#This Row],[$MSN IN]]-Table115[[#This Row],[$MXN OUT]] -> -16350
B29: filling truck | C29: paymenths + food | D29: 45958 | E29: 1 | G29: 2500 | H29: =Table115[[#This Row],[Q]]*Table115[[#This Row],[$MXN OUT]] -> 2500 | K29: =+K28+Table115[[#This Row],[$MSN IN]]-Table115[[#This Row],[$MXN OUT]] -> -18850
B30: house | C30: rent | D30: advance | E30: 1 | G30: 7000 | H30: =Table115[[#This Row],[Q]]*Table115[[#This Row],[$MXN OUT]] -> 7000 | K30: =+K29+Table115[[#This Row],[$MSN IN]]-Table115[[#This Row],[$MXN OUT]] -> -25850
B31: warehose | C31: rent | D31: november | E31: 1 | G31: 12000 | H31: =Table115[[#This Row],[Q]]*Table115[[#This Row],[$MXN OUT]] -> 12000 | K31: =+K30+Table115[[#This Row],[$MSN IN]]-Table115[[#This Row],[$MXN OUT]] -> -37850
B32: personal | D32: advance | E32: 1 | G32: 10000 | H32: =Table115[[#This Row],[Q]]*Table115[[#This Row],[$MXN OUT]] -> 10000 | K32: =+K31+Table115[[#This Row],[$MSN IN]]-Table115[[#This Row],[$MXN OUT]] -> -47850
A33: 45974 | C33: ATM | D33: withdrawal | E33: 1 | F33: 11900 | H33: =Table115[[#This Row],[Q]]*Table115[[#This Row],[$MXN OUT]] -> 0
A34: 45973 | C34: atm | D34: withdrawal | E34: 1 | F34: 11500 | H34: =Table115[[#This Row],[Q]]*Table115[[#This Row],[$MXN OUT]] -> 0
A35: 45976 | C35: atm | D35: withdrawal | E35: 1 | F35: 11500 | H35: =Table115[[#This Row],[Q]]*Table115[[#This Row],[$MXN OUT]] -> 0
A36: 45978 | C36: atm | D36: withdrawal | E36: 1 | F36: 11500 | H36: =Table115[[#This Row],[Q]]*Table115[[#This Row],[$MXN OUT]] -> 0
A37: 45979 | C37: atm | D37: withdrawal | E37: 1 | F37: 11900 | H37: =Table115[[#This Row],[Q]]*Table115[[#This Row],[$MXN OUT]] -> 0
A38: 46004 | C38: atm | D38: withdrawal | E38: 1 | F38: 2200 | H38: =Table115[[#This Row],[Q]]*Table115[[#This Row],[$MXN OUT]] -> 0
A39: 46004 | C39: atm | D39: withdrawal | E39: 1 | F39: 8000 | H39: =Table115[[#This Row],[Q]]*Table115[[#This Row],[$MXN OUT]] -> 0
A40: 46001 | B40: simona | C40: crates | D40: la cantera | E40: 2 | G40: 1750 | H40: =Table115[[#This Row],[Q]]*Table115[[#This Row],[$MXN OUT]] -> 3500
...

Sheet -vCrates
A1: PALLETS AND CRATES | C1: SIMONA | R1: =R3-R2 -> 3096.9444
A2: OWED | B2: =B3-B4 -> -55745 | R2: =B3/18 -> 0
A3: PAID | B3: =SUM(Table11524[[#All],[$MSN IN]]) -> 0 | R3: =SUM(R6:R14) -> 3096.9444
A4: TBP | B4: =SUM(Table11524[TOTAL $]) -> 55745 | K4: \
A5: Date | B5: VENDOR | C5: ITEM | D5: DESCTIPTION | E5: Q | F5: KG | G5: L CM | H5: W CM | I5: D CM | J5: $MSN IN | K5: $MXN OUT | L5: TOTAL $ | M5: POUNDS | N5: H " | O5: W" | P5: D" | Q5: $USD | R5: TOTAL USD
A6: 46042 | B6: simona | C6: crates | D6: GE. ET.RF, EM | E6: 6 | G6: 120 | H6: 150 | I6: 180 | K6: 3000 | L6: =Table11524[[#This Row],[Q]]*Table11524[[#This Row],[$MXN OUT]] -> 18000 | M6: =F6*2.20462 -> 0 | N6: =G6/2.54 -> 47.244094 | O6: =H6/2.54 -> 59.055118 | P6: =I6/2.54 -> 70.866142 | Q6: =IF(E6>0.1,K6/18," ") -> 166.66667 | R6: =IF(E6>0.1,Q6*E6," ") -> 1000
B7: simona | C7: crates w divisions | D7: EM | E7: 2 | G7: 120 | H7: 150 | I7: 180 | K7: 4200 | L7: =Table11524[[#This Row],[Q]]*Table11524[[#This Row],[$MXN OUT]] -> 8400 | M7: =F7*2.20462 -> 0 | N7: =G7/2.54 -> 47.244094 | O7: =H7/2.54 -> 59.055118 | P7: =I7/2.54 -> 70.866142 | Q7: =IF(E7>0.1,K7/18," ") -> 233.33333 | R7: =IF(E7>0.1,Q7*E7," ") -> 466.66667
B8: simona | C8: crates | D8: EM. GE | E8: 4 | G8: 120 | H8: 120 | I8: 120 | K8: 2150 | L8: =Table11524[[#This Row],[Q]]*Table11524[[#This Row],[$MXN OUT]] -> 8600 | M8: =F8*2.20462 -> 0 | N8: =G8/2.54 -> 47.244094 | O8: =H8/2.54 -> 47.244094 | P8: =I8/2.54 -> 47.244094 | Q8: =IF(E8>0.1,K8/18," ") -> 119.44444 | R8: =IF(E8>0.1,Q8*E8," ") -> 477.77778
B9: simona | C9: CRATES | D9: ML | E9: 2 | G9: 120 | H9: 150 | I9: 170 | K9: 2300 | L9: =Table11524[[#This Row],[Q]]*Table11524[[#This Row],[$MXN OUT]] -> 4600 | M9: =F9*2.20462 -> 0 | N9: =G9/2.54 -> 47.244094 | O9: =H9/2.54 -> 59.055118 | P9: =I9/2.54 -> 66.929134 | Q9: =IF(E9>0.1,K9/18," ") -> 127.77778 | R9: =IF(E9>0.1,Q9*E9," ") -> 255.55556
B10: simona | C10: PALETS | D10: DH | E10: 4 | G10: 180 | H10: 60 | K10: 1100 | L10: =Table11524[[#This Row],[Q]]*Table11524[[#This Row],[$MXN OUT]] -> 4400 | M10: =F10*2.20462 -> 0 | N10: =G10/2.54 -> 70.866142 | O10: =H10/2.54 -> 23.622047 | P10: =I10/2.54 -> 0 | Q10: =IF(E10>0.1,K10/18," ") -> 61.111111 | R10: =IF(E10>0.1,Q10*E10," ") -> 244.44444
B11: simona | C11: CRATES | D11: AM | E11: 1 | G11: 185 | H11: 45 | I11: 75 | K11: 1730 | L11: =Table11524[[#This Row],[Q]]*Table11524[[#This Row],[$MXN OUT]] -> 1730 | M11: =F11*2.20462 -> 0 | N11: =G11/2.54 -> 72.834646 | O11: =H11/2.54 -> 17.716535 | P11: =I11/2.54 -> 29.527559 | Q11: =IF(E11>0.1,K11/18," ") -> 96.111111 | R11: =IF(E11>0.1,Q11*E11," ") -> 96.111111
B12: simona | C12: CRATES | D12: AM | E12: 1 | G12: 200 | H12: 140 | I12: 75 | K12: 3765 | L12: =Table11524[[#This Row],[Q]]*Table11524[[#This Row],[$MXN OUT]] -> 3765 | M12: =F12*2.20462 -> 0 | N12: =G12/2.54 -> 78.740157 | O12: =H12/2.54 -> 55.11811 | P12: =I12/2.54 -> 29.527559 | Q12: =IF(E12>0.1,K12/18," ") -> 209.16667 | R12: =IF(E12>0.1,Q12*E12," ") -> 209.16667
B13: simona | C13: crates | D13: em | E13: 2 | G13: 120 | H13: 150 | I13: 180 | K13: 3000 | L13: =Table11524[[#This Row],[Q]]*Table11524[[#This Row],[$MXN OUT]] -> 6000 | M13: =F13*2.20462 -> 0 | N13: =G13/2.54 -> 47.244094 | O13: =H13/2.54 -> 59.055118 | P13: =I13/2.54 -> 70.866142 | Q13: =IF(E13>0.1,K13/18," ") -> 166.66667 | R13: =IF(E13>0.1,Q13*E13," ") -> 333.33333
B14: simona | C14: CRATE | D14: CH | E14: 1 | G14: 85 | H14: 40 | I14: 15 | K14: 250 | L14: =Table11524[[#This Row],[Q]]*Table11524[[#This Row],[$MXN OUT]] -> 250 | M14: =F14*2.20462 -> 0 | N14: =G14/2.54 -> 33.464567 | O14: =H14/2.54 -> 15.748031 | P14: =I14/2.54 -> 5.9055118 | Q14: =IF(E14>0.1,K14/18," ") -> 13.888889 | R14: =IF(E14>0.1,Q14*E14," ") -> 13.888889

Sheet -TRK1
A2: TRK1 | D2: 45887 | K2: TOTAL | N2: =SUM(N5:N128) -> 666790
B4: date | C4: Description | D4: Tag - ID with LC | E4: LC | F4: AQ CODE | G4: RETAIL | H4: Quantity | I4: Weight KG | J4: length in CM | K4: Width in CM | L4: Depth in | M4: Per piece Pesos | N4: Total in Pesos | O4: pounds | P4: Height in Inches | Q4: Width in inches | R4: Depth in Inches | S4: Per Piece US$ | T4: Total in US$ Dollars | U4: Column1
A5: EM | B5: } | C5: GREY RUSTIC ROCK FTN | D5: EM325055OHL | E5: OOM | F5: MEA | G5: 1768 | H5: 1 | I5: 228 | J5: 129 | K5: 42 | L5: 21 | M5: 2850 | N5: 2850 | O5: 502.65336 | P5: 50.787402 | Q5: 16.535433 | R5: 8.2677165 | S5: 158.33 | T5: 158.33
A6: EM | B6: 2 | C6: GREY RUSTIC ROCK FTN | D6: EM325056OFF | E6: OEM | F6: MFN | G6: 2008 | H6: 1 | I6: 257 | J6: 95 | K6: 45 | L6: 27 | M6: 3212.5 | N6: 3212.5 | O6: 566.58734 | P6: 37.401575 | Q6: 17.716535 | R6: 10.629921 | S6: 178.47 | T6: 178.47
A7: EM | B7: 3 | C7: GREY RUSTIC ROCK FTN | D7: EM325057OHO | E7: OMA | F7: MEL | G7: 1744 | H7: 1 | I7: 224 | J7: 95 | K7: 45 | L7: 23 | M7: 2800 | N7: 2800 | O7: 493.83488 | P7: 37.401575 | Q7: 17.716535 | R7: 9.0551181 | S7: 155.56 | T7: 155.56
A8: EM | B8: 4 | C8: GREY RUSTIC ROCK FTN | D8: EM325058MXL | E8: MOX | F8: AA | G8: 984 | H8: 1 | I8: 126 | J8: 100 | K8: 40 | L8: 23 | M8: 1575 | N8: 1575 | O8: 277.78212 | P8: 39.370079 | Q8: 15.748031 | R8: 9.0551181 | S8: 87.5 | T8: 87.5
A9: EM | B9: 5 | C9: GREY RUSTIC ROCK FTN | D9: EM325060OXH | E9: OMD | F9: MED | G9: 1680 | H9: 1 | I9: 216 | J9: 100 | K9: 45 | L9: 29 | M9: 2700 | N9: 2700 | O9: 476.19792 | P9: 39.370079 | Q9: 17.716535 | R9: 11.417323 | S9: 150 | T9: 150
A10: EM | B10: 6 | C10: GREY RUSTIC ROCK FTN | D10: EM325061NN | E10: ND | F10: LH | G10: 720 | H10: 1 | I10: 92 | J10: 68 | K10: 33 | L10: 23 | M10: 1150 | N10: 1150 | O10: 202.82504 | P10: 26.771654 | Q10: 12.992126 | R10: 9.0551181 | S10: 63.89 | T10: 63.89
A11: EM | B11: 7 | C11: SERPENTINE RUSTIC ROCK FTN | D11: EM325062OAD | E11: OEX | F11: MAM | G11: 2024 | H11: 1 | I11: 260 | J11: 93 | K11: 37 | L11: 40 | M11: 3250 | N11: 3250 | O11: 573.2012 | P11: 36.614173 | Q11: 14.566929 | R11: 15.748031 | S11: 180.56 | T11: 180.56
A12: EM | B12: 8 | C12: SERPENTINE RUSTIC ROCK FTN | D12: EM325063OXH | E12: OMD | F12: MED | G12: 1680 | H12: 1 | I12: 216 | J12: 91 | K12: 42 | L12: 32 | M12: 2700 | N12: 2700 | O12: 476.19792 | P12: 35.826772 | Q12: 16.535433 | R12: 12.598425 | S12: 150 | T12: 150
A13: EM | B13: 9 | C13: SERPENTINE RUSTIC ROCK FTN | D13: EM325064MLO | E13: MHF | F13: MDE | G13: 1176 | H13: 1 | I13: 151 | J13: 88 | K13: 49 | L13: 25 | M13: 1887.5 | N13: 1887.5 | O13: 332.89762 | P13: 34.645669 | Q13: 19.291339 | R13: 9.8425197 | S13: 104.86 | T13: 104.86
A14: EM | B14: 10 | C14: SERPENTINE RUSTIC ROCK FTN | D14: EM325065OHA | E14: OOH | F14: MLD | G14: 1792 | H14: 1 | I14: 230 | J14: 85 | K14: 40 | L14: 34 | M14: 2875 | N14: 2875 | O14: 507.0626 | P14: 33.464567 | Q14: 15.748031 | R14: 13.385827 | S14: 159.72 | T14: 159.72
A15: EM | B15: 11 | C15: PINK SERP RUSTIC ROCK FTN | D15: EM325066HHN | E15: HDL | F15: OND | G15: 3248 | H15: 1 | I15: 417 | J15: 68 | K15: 99 | L15: 42 | M15: 5212.5 | N15: 5212.5 | O15: 919.32654 | P15: 26.771654 | Q15: 38.976378 | R15: 16.535433 | S15: 289.58 | T15: 289.58
A16: EM | B16: 12 | C16: PINK SERP RUSTIC ROCK FTN | D16: EM325067AA | E16: AD | F16: EF | G16: 640 | H16: 1 | I16: 82 | J16: 80 | K16: 31 | L16: 18 | M16: 1025 | N16: 1025 | O16: 180.77884 | P16: 31.496063 | Q16: 12.204724 | R16: 7.0866142 | S16: 56.94 | T16: 56.94
A17: EM | B17: 13 | C17: PINK SERP RUSTIC ROCK FTN | D17: EM325068OFF | E17: OEM | F17: MFN | G17: 2008 | H17: 1 | I17: 257 | J17: 121 | K17: 60 | L17: 27 | M17: 3212.5 | N17: 3212.5 | O17: 566.58734 | P17: 47.637795 | Q17: 23.622047 | R17: 10.629921 | S17: 178.47 | T17: 178.47
... A21: EM | B21: 17 | C21: GREY RUSTIC ROCK FTN | D21: EM325074AA | E21: AD | F21: EF | G21: 640 | H21: 1 | I21: 82 | J21: 70 | K21: 34 | L21: 18 | M21: 1025 | N21: 1025 | O21: 180.77884 | P21: 27.559055 | Q21: 13.385827 | R21: 7.0866142 | S21: 56.94 | T21: 56.94
A22: EM | B22: 20 | C22: GRAY REC MIRROR | D22: EM82520XNL | E22: XNL | F22: OAX | G22: 3168 | H22: 1 | I22: 30 | J22: 150 | K22: 80 | M22: 5100 | N22: 5100 | O22: 66.1386 | P22: 59.055118 | Q22: 31.496063 | R22: 0 | S22: 283.33 | T22: 283.33
A23: EM | B23: 21 | C23: GRAY REC MIRROR | D23: EM82521XNL | E23: XNL | F23: OAX | G23: 3168 | H23: 1 | I23: 30 | J23: 150 | K23: 80 | M23: 5100 | N23: 5100 | O23: 66.1386 | P23: 59.055118 | Q23: 31.496063 | R23: 0 | S23: 283.33 | T23: 283.33
A24: EM | B24: 22 | C24: AMBER REC MIRROR | D24: EM82522XNL | E24: XNL | F24: OAX | G24: 3168 | H24: 1 | I24: 30 | J24: 150 | K24: 80 | M24: 5100 | N24: 5100 | O24: 66.1386 | P24: 59.055118 | Q24: 31.496063 | R24: 0 | S24: 283.33 | T24: 283.33
A25: EM | B25: 23 | C25: AMBER REC MIRROR | D25: EM82523XNL | E25: XNL | F25: OAX | G25: 3168 | H25: 1 | I25: 30 | J25: 150 | K25: 80 | M25: 5100 | N25: 5100 | O25: 66.1386 | P25: 59.055118 | Q25: 31.496063 | R25: 0 | S25: 283.33 | T25: 283.33
A26: EM | B26: 24 | C26: CRYSTALLINE REC MIRROR | D26: EM82524XNL | E26: XNL | F26: OAX | G26: 3168 | H26: 1 | I26: 30 | J26: 150 | K26: 80 | M26: 5100 | N26: 5100 | O26: 66.1386 | P26: 59.055118 | Q26: 31.496063 | R26: 0 | S26: 283.33 | T26: 283.33
A27: EM | B27: 25 | C27: CRYS REC MIRROR | D27: EM82525XNL | E27: XNL | F27: OAX | G27: 3168 | H27: 1 | I27: 30 | J27: 150 | K27: 80 | M27: 5100 | N27: 5100 | O27: 66.1386 | P27: 59.055118 | Q27: 31.496063 | R27: 0 | S27: 283.33 | T27: 283.33
A28: EM | B28: 26 | C28: CRYS REC MIRROR | D28: EM82526XNL | E28: XNL | F28: OAX | G28: 3168 | H28: 1 | I28: 30 | J28: 150 | K28: 80 | M28: 5100 | N28: 5100 | O28: 66.1386 | P28: 59.055118 | Q28: 31.496063 | R28: 0 | S28: 283.33 | T28: 283.33
A29: EM | B29: 27 | C29: CRYS REC MIRROR | D29: EM82527XNL | E29: XNL | F29: OAX | G29: 3168 | H29: 1 | I29: 30 | J29: 150 | K29: 80 | M29: 5100 | N29: 5100 | O29: 66.1386 | P29: 59.055118 | Q29: 31.496063 | R29: 0 | S29: 283.33 | T29: 283.33
A30: EM | B30: 28 | C30: CRYS REC MIRROR | D30: EM82528XNL | E30: XNL | F30: OAX | G30: 3168 | H30: 1 | I30: 30 | J30: 150 | K30: 80 | M30: 5100 | N30: 5100 | O30: 66.1386 | P30: 59.055118 | Q30: 31.496063 | R30: 0 | S30: 283.33 | T30: 283.33
A31: EM | B31: 29 | C31: CRYS REC MIRROR | D31: EM82529XNL | E31: XNL | F31: OAX | G31: 3168 | H31: 1 | I31: 30 | J31: 150 | K31: 80 | M31: 5100 | N31: 5100 | O31: 66.1386 | P31: 59.055118 | Q31: 31.496063 | R31: 0 | S31: 283.33 | T31: 283.33
A32: EM | B32: 30 | C32: CRYS REC MIRROR | D32: EM82530XNL | E32: XNL | F32: OAX | G32: 3168 | H32: 1 | I32: 30 | J32: 150 | K32: 80 | M32: 5100 | N32: 5100 | O32: 66.1386 | P32: 59.055118 | Q32: 31.496063 | R32: 0 | S32: 283.33 | T32: 283.33
A33: EM | B33: 31 | C33: CRYS REC MIRROR | D33: EM82531XNL | E33: XNL | F33: OAX | G33: 3168 | H33: 1 | I33: 30 | J33: 150 | K33: 80 | M33: 5100 | N33: 5100 | O33: 66.1386 | P33: 59.055118 | Q33: 31.496063 | R33: 0 | S33: 283.33 | T33: 283.33
... A74: EM | B74: 72 | C74: CRIS GREY REC MIRROR | D74: EM82572XNL | E74: XNL | F74: OAX | G74: 3168 | H74: 1 | I74: 30 | J74: 150 | K74: 80 | M74: 5100 | N74: 5100 | O74: 66.1386 | P74: 59.055118 | Q74: 31.496063 | R74: 0 | S74: 283.33 | T74: 283.33
A75: EM | B75: 73 | C75: CRIS GREY RD MIRROR | D75: EM82573XOL | E75: XOL | F75: OXX | G75: 2608 | H75: 6 | I75: 13 | J75: 80 | M75: 4200 | N75: 25200 | O75: 28.66006 | P75: 31.496063 | Q75: 0 | R75: 0 | S75: 233.33 | T75: 1400
A76: EM | B76: 74 | C76: CRIS GREY REC MIRROR | D76: EM82574OLE | E76: OLE | F76: MAN | G76: 2120 | H76: 5 | I76: 19 | J76: 110 | K76: 60 | M76: 3400 | N76: 17000 | O76: 41.88778 | P76: 43.307087 | Q76: 23.622047 | R76: 0 | S76: 188.89 | T76: 944.44
A77: EM | B77: 75 | C77: TEHUA/GREY DIAMOND TABLE | D77: EM82575LOX | E77: LOX | F77: HHE | G77: 4984 | H77: 1 | I77: 52 | J77: 86 | K77: 86 | L77: 50 | M77: 8000 | N77: 8000 | O77: 114.64024 | P77: 33.858268 | Q77: 33.858268 | R77: 19.685039 | S77: 444.44 | T77: 444.44
A78: TE | B78: 1 | C78: ZEBRA PANEL SET | D78: TE82501MFMO | E78: MFMO | F78: MOOX | G78: 13696 | H78: 1 | I78: 155 | J78: 210 | K78: 40 | L78: 10 | M78: 22015 | N78: 22015 | O78: 341.7161 | P78: 82.677165 | Q78: 15.748031 | R78: 3.9370079 | S78: 1223.06 | T78: 1223.06
A79: TE | B79: 2 | C79: BEIGE MARBLE AMORE SCULPTURE | D79: TE82502MNMM | E79: MNMM | F79: MXLE | G79: 15288 | H79: 1 | I79: 250 | J79: 170 | M79: 24565 | N79: 24565 | O79: 551.155 | P79: 66.929134 | Q79: 0 | R79: 0 | S79: 1364.72 | T79: 1364.72
A80: TE | B80: 3 | C80: GREEN TALAN PANEL SET | D80: TE82503MEED | E80: MEED | F80: MMDF | G80: 12400 | H80: 1 | I80: 120 | J80: 190 | K80: 60 | L80: 10 | M80: 19932.5 | N80: 19932.5 | O80: 264.5544 | P80: 74.80315 | Q80: 23.622047 | R80: 3.9370079 | S80: 1107.36 | T80: 1107.36
A81: TE | B81: 4 | C81: BLUE ONIX SOL | D81: TE82504MFXD | E81: MFXD | F81: MOXL | G81: 13840 | H81: 1 | I81: 50 | J81: 160 | K81: 30 | L81: 30 | M81: 22240 | N81: 22240 | O81: 110.231 | P81: 62.992126 | Q81: 11.811024 | R81: 11.811024 | S81: 1235.56 | T81: 1235.56
A82: TE | B82: 5 | C82: BLUE ONIX SOL | D82: TE82505MEFM | E82: MEFM | F82: MMOO | G82: 12568 | H82: 1 | I82: 45 | J82: 145 | K82: 30 | L82: 30 | M82: 20200 | N82: 20200 | O82: 99.2079 | P82: 57.086614 | Q82: 11.811024 | R82: 11.811024 | S82: 1122.22 | T82: 1122.22
A83: TE | B83: 6 | C83: BLUE ONIX SOL | D83: TE82506MHMA | E83: MHMA | F83: MDMX | G83: 11344 | H83: 1 | I83: 40 | J83: 130 | K83: 30 | L83: 30 | M83: 18224 | N83: 18224 | O83: 88.1848 | P83: 51.181102 | Q83: 11.811024 | R83: 11.811024 | S83: 1012.44 | T83: 1012.44
A84: TE | B84: 7 | C84: RED MARBLE AMORE SCULPTURE | D84: TE82507LFN | E84: LFN | F84: HAE | G84: 5432 | H84: 1 | I84: 52 | J84: 100 | M84: 8720 | N84: 8720 | O84: 114.64024 | P84: 39.370079 | Q84: 0 | R84: 0 | S84: 484.44 | T84: 484.44
A85: TE | B85: 8 | C85: PINK SER SOL | D85: TE82508MEE | E85: MEE | F85: MMM | G85: 1240 | H85: 3 | I85: 8 | J85: 60 | K85: 20 | L85: 20 | M85: 1992 | N85: 5976 | O85: 17.63696 | P85: 23.622047 | Q85: 7.8740157 | R85: 7.8740157 | S85: 110.67 | T85: 332
...

Sheet -TRK2
A2: TRK2 | K2: TOTAL | N2: =SUM(N5:N128) -> 493962.54
B4: date | C4: Description | D4: Tag - ID with LC | E4: LC | F4: AQ CODE | G4: RETAIL | H4: Quantity | I4: Weight KG | J4: length in CM | K4: Width in CM | L4: Depth in | M4: Per piece Pesos | N4: Total in Pesos | O4: pounds | P4: Height in Inches | Q4: Width in inches | R4: Depth in Inches | S4: Per Piece US$ | T4: Total in US$ Dollars
C5: COL ONYX ICE | D5: ML82501XO | E5: XO | F5: OX | H5: 12 | J5: 40 | K5: 12 | L5: 12 | M5: 420 | N5: =M5*H5 -> 5040 | O5: =IF(I5>0.1,I5*2.20462," ") | P5: =J5/2.54 -> 15.748031 | Q5: =K5/2.54 -> 4.7244094 | R5: =L5/2.54 -> 4.7244094 | S5: =M5/18 -> 23.333333 | T5: =S5*H5 -> 280
C6: COL ONYX ICE | D6: ML82502HA | E6: HA | F6: XH | H6: 5 | J6: 40 | K6: 16 | L6: 16 | M6: 605 | N6: =M6*H6 -> 3025 | O6: =IF(I6>0.1,I6*2.20462," ") | P6: =J6/2.54 -> 15.748031 | Q6: =K6/2.54 -> 6.2992126 | R6: =L6/2.54 -> 6.2992126 | S6: =M6/18 -> 33.611111 | T6: =S6*H6 -> 168.05556
C7: COL ONYX ICE | D7: ML82503XO | E7: XO | F7: OX | H7: 10 | J7: 35 | K7: 12 | L7: 12 | M7: 410 | N7: =M7*H7 -> 4100 | O7: =IF(I7>0.1,I7*2.20462," ") | P7: =J7/2.54 -> 13.779528 | Q7: =K7/2.54 -> 4.7244094 | R7: =L7/2.54 -> 4.7244094 | S7: =M7/18 -> 22.777778 | T7: =S7*H7 -> 227.77778
C8: COL ONYX ICE | D8: ML82504OA | E8: OA | F8: OD | H8: 23 | J8: 30 | K8: 12 | L8: 12 | M8: 350 | N8: =M8*H8 -> 8050 | O8: =IF(I8>0.1,I8*2.20462," ") | P8: =J8/2.54 -> 11.811024 | Q8: =K8/2.54 -> 4.7244094 | R8: =L8/2.54 -> 4.7244094 | S8: =M8/18 -> 19.444444 | T8: =S8*H8 -> 447.22222
C9: COL ONYX ICE | D9: ML82505XL | E9: XL | F9: OL | H9: 7 | J9: 30 | K9: 16 | L9: 16 | M9: 460 | N9: =M9*H9 -> 3220 | O9: =IF(I9>0.1,I9*2.20462," ") | P9: =J9/2.54 -> 11.811024 | Q9: =K9/2.54 -> 6.2992126 | R9: =L9/2.54 -> 6.2992126 | S9: =M9/18 -> 25.555556 | T9: =S9*H9 -> 178.88889
C10: COL ONYX ICE | D10: ML82506MH | E10: MH | F10: MD | H10: 5 | J10: 25 | K10: 8 | L10: 8 | M10: 180 | N10: =M10*H10 -> 900 | O10: =IF(I10>0.1,I10*2.20462," ") | P10: =J10/2.54 -> 9.8425197 | Q10: =K10/2.54 -> 3.1496063 | R10: =L10/2.54 -> 3.1496063 | S10: =M10/18 -> 10 | T10: =S10*H10 -> 50
C11: AQUA SERP REC MIRROR | D11: EM82576XNL | E11: XNL | F11: OAX | H11: 2 | I11: 30 | J11: 150 | K11: 80 | L11: 10 | M11: 5100 | N11: =M11*H11 -> 10200 | O11: =IF(I11>0.1,I11*2.20462," ") -> 66.1386 | P11: =J11/2.54 -> 59.055118 | Q11: =K11/2.54 -> 31.496063 | R11: =L11/2.54 -> 3.9370079 | S11: =M11/18 -> 283.33333 | T11: =S11*H11 -> 566.66667
C12: TEHUA GREY REC MIRROR | D12: EM82577XNL | E12: XNL | F12: OAX | H12: 4 | I12: 30 | J12: 150 | K12: 80 | L12: 10 | M12: 5100 | N12: =M12*H12 -> 20400 | O12: =IF(I12>0.1,I12*2.20462," ") -> 66.1386 | P12: =J12/2.54 -> 59.055118 | Q12: =K12/2.54 -> 31.496063 | R12: =L12/2.54 -> 3.9370079 | S12: =M12/18 -> 283.33333 | T12: =S12*H12 -> 1133.3333
C13: CRISTALINO REC MIRROR | D13: EM82578ENM | E13: ENM | F13: HOO | H13: 1 | I13: 40 | J13: 183 | K13: 102 | L13: 10 | M13: 7600 | N13: =M13*H13 -> 7600 | O13: =IF(I13>0.1,I13*2.20462," ") -> 88.1848 | P13: =J13/2.54 -> 72.047244 | Q13: =K13/2.54 -> 40.15748 | R13: =L13/2.54 -> 3.9370079 | S13: =M13/18 -> 422.22222 | T13: =S13*H13 -> 422.22222
C14: CRIS GREY SQ MIRROR | D14: EM82579XOL | E14: XOL | F14: OXX | H14: 3 | I14: 27 | J14: 100 | K14: 100 | L14: 10 | M14: 4200 | N14: =M14*H14 -> 12600 | O14: =IF(I14>0.1,I14*2.20462," ") -> 59.52474 | P14: =J14/2.54 -> 39.370079 | Q14: =K14/2.54 -> 39.370079 | R14: =L14/2.54 -> 3.9370079 | S14: =M14/18 -> 233.33333 | T14: =S14*H14 -> 700
C15: TEHUA GREY REC MIRROR | D15: EM82580OLE | E15: OLE | F15: MAN | H15: 2 | I15: 19 | J15: 110 | K15: 60 | L15: 10 | M15: 3400 | N15: =M15*H15 -> 6800 | O15: =IF(I15>0.1,I15*2.20462," ") -> 41.88778 | P15: =J15/2.54 -> 43.307087 | Q15: =K15/2.54 -> 23.622047 | R15: =L15/2.54 -> 3.9370079 | S15: =M15/18 -> 188.88889 | T15: =S15*H15 -> 377.77778
C16: CRISTALINO CANOE | D16: EM82581OFO | E16: OFO | F16: MNH | H16: 1 | J16: 120 | K16: 22 | L16: 11 | M16: 3484 | N16: =M16*H16 -> 3484 | O16: =IF(I16>0.1,I16*2.20462," ") | P16: =J16/2.54 -> 47.244094 | Q16: =K16/2.54 -> 8.6614173 | R16: =L16/2.54 -> 4.3307087 | S16: =M16/18 -> 193.55556 | T16: =S16*H16 -> 193.55556
C17: CRISTALINO CANOE | D17: EM82582OLD | E17: OLD | F17: MAL | H17: 1 | J17: 115 | K17: 22 | L17: 11 | M17: 3339 | N17: =M17*H17 -> 3339 | O17: =IF(I17>0.1,I17*2.20462," ") | P17: =J17/2.54 -> 45.275591 | Q17: =K17/2.54 -> 8.6614173 | R17: =L17/2.54 -> 4.3307087 | S17: =M17/18 -> 185.5 | T17: =S17*H17 -> 185.5
C18: CRISTALINO AMBER CANOE | D18: EM82583OHN | E18: OHN | F18: MFA | H18: 3 | J18: 110 | K18: 22 | L18: 11 | M18: 3194 | N18: =M18*H18 -> 9582 | O18: =IF(I18>0.1,I18*2.20462," ") | P18: =J18/2.54 -> 43.307087 | Q18: =K18/2.54 -> 8.6614173 | R18: =L18/2.54 -> 4.3307087 | S18: =M18/18 -> 177.44444 | T18: =S18*H18 -> 532.33333
C19: CRISTALINO CANOE | D19: EM82584OOE | E19: OOE | F19: MLM | H19: 2 | J19: 110 | K19: 22 | L19: 11 | M19: 2904 | N19: =M19*H19 -> 5808 | O19: =IF(I19>0.1,I19*2.20462," ") | P19: =J19/2.54 -> 43.307087 | Q19: =K19/2.54 -> 8.6614173 | R19: =L19/2.54 -> 4.3307087 | S19: =M19/18 -> 161.33333 | T19: =S19*H19 -> 322.66667
C20: CRISTALINO GREEN CANOE | D20: EM82585MEA | E20: MEA | F20: MMX | H20: 2 | J20: 70 | K20: 22 | L20: 11 | M20: 2032 | N20: =M20*H20 -> 4064 | O20: =IF(I20>0.1,I20*2.20462," ") | P20: =J20/2.54 -> 27.559055 | Q20: =K20/2.54 -> 8.6614173 | R20: =L20/2.54 -> 4.3307087 | S20: =M20/18 -> 112.88889 | T20: =S20*H20 -> 225.77778
C21: CRISTALINO COL | D21: EM82586EN | E21: EN | F21: HO | H21: 18 | I21: 7 | J21: 45 | K21: 15 | L21: 15 | M21: 750 | N21: =M21*H21 -> 13500 | O21: =IF(I21>0.1,I21*2.20462," ") -> 15.43234 | P21: =J21/2.54 -> 17.716535 | Q21: =K21/2.54 -> 5.9055118 | R21: =L21/2.54 -> 5.9055118 | S21: =M21/18 -> 41.666667 | T21: =S21*H21 -> 750
C22: CRISTALINO POL | D22: EM82587XN | E22: XN | F22: OA | H22: 12 | I22: 4 | J22: 40 | K22: 12 | L22: 12 | M22: 500 | N22: =M22*H22 -> 6000 | O22: =IF(I22>0.1,I22*2.20462," ") -> 8.81848 | P22: =J22/2.54 -> 15.748031 | Q22: =K22/2.54 -> 4.7244094 | R22: =L22/2.54 -> 4.7244094 | S22: =M22/18 -> 27.777778 | T22: =S22*H22 -> 333.33333
C23: CRISTALINO POL | D23: EM82588ON | E23: ON | F23: OM | H23: 18 | I23: 3 | J23: 35 | K23: 10 | L23: 10 | M23: 380 | N23: =M23*H23 -> 6840 | O23: =IF(I23>0.1,I23*2.20462," ") -> 6.61386 | P23: =J23/2.54 -> 13.779528 | Q23: =K23/2.54 -> 3.9370079 | R23: =L23/2.54 -> 3.9370079 | S23: =M23/18 -> 21.111111 | T23: =S23*H23 -> 380
C24: GREY POL | D24: EM82589ON | E24: ON | F24: OM | H24: 13 | I24: 3 | J24: 35 | K24: 10 | L24: 10 | M24: 380 | N24: =M24*H24 -> 4940 | O24: =IF(I24>0.1,I24*2.20462," ") -> 6.61386 | P24: =J24/2.54 -> 13.779528 | Q24: =K24/2.54 -> 3.9370079 | R24: =L24/2.54 -> 3.9370079 | S24: =M24/18 -> 21.111111 | T24: =S24*H24 -> 274.44444
C25: CRIS AMBAR POL | D25: EM82590ON | E25: ON | F25: OM | H25: 23 | I25: 3 | J25: 35 | K25: 10 | L25: 10 | M25: 380 | N25: =M25*H25 -> 8740 | O25: =IF(I25>0.1,I25*2.20462," ") -> 6.61386 | P25: =J25/2.54 -> 13.779528 | Q25: =K25/2.54 -> 3.9370079 | R25: =L25/2.54 -> 3.9370079 | S25: =M25/18 -> 21.111111 | T25: =S25*H25 -> 485.55556
C26: CRISTALINO POL | D26: EM82591XE | E26: XE | F26: OE | H26: 14 | I26: 3 | J26: 35 | K26: 12 | L26: 12 | M26: 440 | N26: =M26*H26 -> 6160 | O26: =IF(I26>0.1,I26*2.20462," ") -> 6.61386 | P26: =J26/2.54 -> 13.779528 | Q26: =K26/2.54 -> 4.7244094 | R26: =L26/2.54 -> 4.7244094 | S26: =M26/18 -> 24.444444 | T26: =S26*H26 -> 342.22222
C27: CANOE | D27: JM8254491HDX | E27: HDX | F27: OAA | H27: 1 | J27: 130 | K27: 24 | L27: 10 | M27: 7400 | N27: =M27*H27 -> 7400 | O27: =IF(I27>0.1,I27*2.20462," ") | P27: =J27/2.54 -> 51.181102 | Q27: =K27/2.54 -> 9.4488189 | R27: =L27/2.54 -> 3.9370079 | S27: =M27/18 -> 411.11111 | T27: =S27*H27 -> 411.11111
C28: CANOE | D28: JM8254546EOO | E28: EOO | F28: XFX | H28: 1 | J28: 150 | K28: 24 | L28: 24 | M28: 9600 | N28: =M28*H28 -> 9600 | O28: =IF(I28>0.1,I28*2.20462," ") | P28: =J28/2.54 -> 59.055118 | Q28: =K28/2.54 -> 9.4488189 | R28: =L28/2.54 -> 9.4488189 | S28: =M28/18 -> 533.33333 | T28: =S28*H28 -> 533.33333
C29: CANOE | D29: JM8254574FF | E29: FF | F29: EE | H29: 1 | J29: 130 | K29: 24 | L29: 24 | M29: 1400 | N29: =M29*H29 -> 1400 | O29: =IF(I29>0.1,I29*2.20462," ") | P29: =J29/2.54 -> 51.181102 | Q29: =K29/2.54 -> 9.4488189 | R29: =L29/2.54 -> 9.4488189 | S29: =M29/18 -> 77.777778 | T29: =S29*H29 -> 77.777778
C30: CANOE | D30: JM8254418EOO | E30: EOO | F30: XFX | H30: 1 | J30: 150 | K30: 24 | L30: 24 | M30: 9600 | N30: =M30*H30 -> 9600 | O30: =IF(I30>0.1,I30*2.20462," ") | P30: =J30/2.54 -> 59.055118 | Q30: =K30/2.54 -> 9.4488189 | R30: =L30/2.54 -> 9.4488189 | S30: =M30/18 -> 533.33333 | T30: =S30*H30 -> 533.33333
C31: CANOE | D31: JM8254494HEA | E31: HEA | F31: XOF | H31: 1 | J31: 140 | K31: 24 | L31: 24 | M31: 8400 | N31: =M31*H31 -> 8400 | O31: =IF(I31>0.1,I31*2.20462," ") | P31: =J31/2.54 -> 55.11811 | Q31: =K31/2.54 -> 9.4488189 | R31: =L31/2.54 -> 9.4488189 | S31: =M31/18 -> 466.66667 | T31: =S31*H31 -> 466.66667
C32: CANOE | D32: JM8254542OFX | E32: OFX | F32: MNE | H32: 1 | J32: 95 | K32: 24 | L32: 24 | M32: 5000 | N32: =M32*H32 -> 5000 | O32: =IF(I32>0.1,I32*2.20462," ") | P32: =J32/2.54 -> 37.401575 | Q32: =K32/2.54 -> 9.4488189 | R32: =L32/2.54 -> 9.4488189 | S32: =M32/18 -> 277.77778 | T32: =S32*H32 -> 277.77778
C33: PLATE | D33: JM8253649EHE | E33: EHE | F33: XAN | H33: 1 | J33: 60 | K33: 60 | L33: 9 | M33: 10000 | N33: =M33*H33 -> 10000 | O33: =IF(I33>0.1,I33*2.20462," ") | P33: =J33/2.54 -> 23.622047 | Q33: =K33/2.54 -> 23.622047 | R33: =L33/2.54 -> 3.5433071 | S33: =M33/18 -> 555.55556 | T33: =S33*H33 -> 555.55556
C34: CANOE | D34: JM8254932HDX | E34: HDX | F34: OAA | H34: 1 | J34: 130 | K34: 23 | L34: 10 | M34: 7400 | N34: =M34*H34 -> 7400 | O34: =IF(I34>0.1,I34*2.20462," ") | P34: =J34/2.54 -> 51.181102 | Q34: =K34/2.54 -> 9.0551181 | R34: =L34/2.54 -> 3.9370079 | S34: =M34/18 -> 411.11111 | T34: =S34*H34 -> 411.11111
C35: CANOE | D35: JM8254933HEA | E35: HEA | F35: XOF | H35: 1 | J35: 140 | K35: 23 | L35: 10 | M35: 8400 | N35: =M35*H35 -> 8400 | O35: =IF(I35>0.1,I35*2.20462," ") | P35: =J35/2.54 -> 55.11811 | Q35: =K35/2.54 -> 9.0551181 | R35: =L35/2.54 -> 3.9370079 | S35: =M35/18 -> 466.66667 | T35: =S35*H35 -> 466.66667
C36: CANOE | D36: JM8254970HDX | E36: HDX | F36: OAA | H36: 1 | J36: 130 | K36: 23 | L36: 10 | M36: 7400 | N36: =M36*H36 -> 7400 | O36: =IF(I36>0.1,I36*2.20462," ") | P36: =J36/2.54 -> 51.181102 | Q36: =K36/2.54 -> 9.0551181 | R36: =L36/2.54 -> 3.9370079 | S36: =M36/18 -> 411.11111 | T36: =S36*H36 -> 411.11111
C37: CANOE | D37: JM8254972HDX | E37: HDX | F37: OAA | H37: 1 | J37: 130 | K37: 23 | L37: 10 | M37: 7400 | N37: =M37*H37 -> 7400 | O37: =IF(I37>0.1,I37*2.20462," ") | P37: =J37/2.54 -> 51.181102 | Q37: =K37/2.54 -> 9.0551181 | R37: =L37/2.54 -> 3.9370079 | S37: =M37/18 -> 411.11111 | T37: =S37*H37 -> 411.11111
C38: PLATE | D38: JM8255114MXLM | E38: MXLM | F38: NFO | H38: 1 | J38: 86 | K38: 23 | L38: 24 | M38: 25000 | N38: =M38*H38 -> 25000 | O38: =IF(I38>0.1,I38*2.20462," ") | P38: =J38/2.54 -> 33.858268 | Q38: =K38/2.54 -> 9.0551181 | R38: =L38/2.54 -> 9.4488189 | S38: =M38/18 -> 1388.8889 | T38: =S38*H38 -> 1388.8889
C39: ZEBRA RUSTIC FOUNTAIN | D39: DH82501HAF | E39: HAF | F39: XHA | H39: 1 | I39: 476 | J39: 147 | K39: 34 | L39: 40 | M39: 6254.64 | N39: =M39*H39 -> 6254.64 | O39: =IF(I39>0.1,I39*2.20462," ") -> 1049.3991 | P39: =J39/2.54 -> 57.874016 | Q39: =K39/2.54 -> 13.385827 | R39: =L39/2.54 -> 15.748031 | S39: =M39/18 -> 347.48 | T39: =S39*H39 -> 347.48
C40: ZEBRA RUSTIC FOUNTAIN | D40: DH82502MDHD | E40: MDHD | F40: FHX | H40: 1 | I40: 1017 | J40: 167 | K40: 65 | L40: 50 | M40: 13363.38 | N40: =M40*H40 -> 13363.38 | O40: =IF(I40>0.1,I40*2.20462," ") -> 2242.0985 | P40: =J40/2.54 -> 65.748031 | Q40: =K40/2.54 -> 25.590551 | R40: =L40/2.54 -> 19.685039 | S40: =M40/18 -> 742.41 | T40: =S40*H40 -> 742.41
C41: ZEBRA RUSTIC FOUNTAIN | D41: DH82503MDFD | E41: MDFD | F41: FLH | H41: 1 | I41: 1047 | J41: 155 | K41: 80 | L41: 56 | M41: 13757.58 | N41: =M41*H41 -> 13757.58 | O41: =IF(I41>0.1,I41*2.20462," ") -> 2308.2371 | P41: =J41/2.54 -> 61.023622 | Q41: =K41/2.54 -> 31.496063 | R41: =L41/2.54 -> 22.047244 | S41: =M41/18 -> 764.31 | T41: =S41*H41 -> 764.31
C42: ZEBRA RUSTIC FOUNTAIN | D42: DH82504EEF | E42: EEF | F42: XNA | H42: 1 | I42: 545 | J42: 171 | K42: 35 | L42: 38 | M42: 7161.3 | N42: =M42*H42 -> 7161.3 | O42: =IF(I42>0.1,I42*2.20462," ") -> 1201.5179 | P42: =J42/2.54 -> 67.322835 | Q42: =K42/2.54 -> 13.779528 | R42: =L42/2.54 -> 14.96063 | S42: =M42/18 -> 397.85 | T42: =S42*H42 -> 397.85
...

Sheet -TRK3
A2: TRK3 | E2: 28/10/26 | K2: TOTAL | N2: =SUM(N5:N127) -> 253320.36
B4: date | C4: Description | D4: Tag - ID with LC | E4: LC | F4: AQ CODE | G4: RETAIL | H4: Quantity | I4: Weight KG | J4: length in CM | K4: Width in CM | L4: Depth in | M4: Per piece Pesos | N4: Total in Pesos | O4: pounds | P4: Height in Inches | Q4: Width in inches | R4: Depth in Inches | S4: Per Piece US$ | T4: Total in US$ Dollars
C5: CACTUS SET (4) PCS | D5: AN82501NXH | E5: NXH | F5: LLF | H5: 1 | I5: 385 | J5: 60 | K5: 32 | M5: 12000 | N5: =M5*H5 -> 12000 | O5: =IF(I5>0.1,I5*2.20462," ") -> 848.7787 | P5: =J5/2.54 -> 23.622047 | Q5: =K5/2.54 -> 12.598425 | R5: =L5/2.54 -> 0 | S5: =M5/18 -> 666.66667 | T5: =S5*H5 -> 666.66667
C6: COL ONYX ICE | D6: ML82507HA | E6: HA | F6: XH | H6: 6 | I6: 8 | J6: 40 | K6: 16 | M6: 605 | N6: =M6*H6 -> 3630 | O6: =IF(I6>0.1,I6*2.20462," ") -> 17.63696 | P6: =J6/2.54 -> 15.748031 | Q6: =K6/2.54 -> 6.2992126 | R6: =L6/2.54 -> 0 | S6: =M6/18 -> 33.611111 | T6: =S6*H6 -> 201.66667
C7: SPHERE FOUNTAIN | D7: CP82501MMLL | E7: MMLL | F7: AXX | H7: 2 | I7: 480 | J7: 70 | M7: 15000 | N7: =M7*H7 -> 30000 | O7: =IF(I7>0.1,I7*2.20462," ") -> 1058.2176 | P7: =J7/2.54 -> 27.559055 | Q7: =K7/2.54 -> 0 | R7: =L7/2.54 -> 0 | S7: =M7/18 -> 833.33333 | T7: =S7*H7 -> 1666.6667
C8: RUSTIC TOWER SET (3) | D8: DH325036EAH | E8: EFE | F8: HMM | H8: 1 | I8: 563 | M8: 7397.82 | N8: =M8*H8 -> 7397.82 | O8: =IF(I8>0.1,I8*2.20462," ") -> 1241.2011 | P8: =J8/2.54 -> 0 | Q8: =K8/2.54 -> 0 | R8: =L8/2.54 -> 0 | S8: =M8/18 -> 410.99 | T8: =S8*H8 -> 410.99
C9: ORANGE FOUNTAIN ROCK | D9: DH82529LAF | E9: LAF | F9: HNM | H9: 1 | I9: 672 | M9: 8830.08 | N9: =M9*H9 -> 8830.08 | O9: =IF(I9>0.1,I9*2.20462," ") -> 1481.5046 | P9: =J9/2.54 -> 0 | Q9: =K9/2.54 -> 0 | R9: =L9/2.54 -> 0 | S9: =M9/18 -> 490.56 | T9: =S9*H9 -> 490.56
C10: ORANGE FOUNTAIN ROCK | D10: DH82530ELX | E10: ELX | F10: HDO | H10: 1 | I10: 551 | M10: 7240.14 | N10: =M10*H10 -> 7240.14 | O10: =IF(I10>0.1,I10*2.20462," ") -> 1214.7456 | P10: =J10/2.54 -> 0 | Q10: =K10/2.54 -> 0 | R10: =L10/2.54 -> 0 | S10: =M10/18 -> 402.23 | T10: =S10*H10 -> 402.23
C11: ORANGE FOUNTAIN ROCK | D11: DH82531FHM | E11: FHM | F11: EON | H11: 1 | I11: 725 | M11: 9526.5 | N11: =M11*H11 -> 9526.5 | O11: =IF(I11>0.1,I11*2.20462," ") -> 1598.3495 | P11: =J11/2.54 -> 0 | Q11: =K11/2.54 -> 0 | R11: =L11/2.54 -> 0 | S11: =M11/18 -> 529.25 | T11: =S11*H11 -> 529.25
C12: ORANGE FOUNTAIN ROCK | D12: DH82534AMM | E12: AMM | F12: EFN | H12: 1 | I12: 793 | M12: 10420.02 | N12: =M12*H12 -> 10420.02 | O12: =IF(I12>0.1,I12*2.20462," ") -> 1748.2637 | P12: =J12/2.54 -> 0 | Q12: =K12/2.54 -> 0 | R12: =L12/2.54 -> 0 | S12: =M12/18 -> 578.89 | T12: =S12*H12 -> 578.89
C13: ORANGE FOUNTAIN ROCK | D13: DH82535EON | E13: EON | F13: XFA | H13: 1 | I13: 518 | M13: 6806.52 | N13: =M13*H13 -> 6806.52 | O13: =IF(I13>0.1,I13*2.20462," ") -> 1141.9932 | P13: =J13/2.54 -> 0 | Q13: =K13/2.54 -> 0 | R13: =L13/2.54 -> 0 | S13: =M13/18 -> 378.14 | T13: =S13*H13 -> 378.14
C14: ORANGE FOUNTAIN ROCK | D14: DH82538FEF | E14: FEF | F14: EHM | H14: 1 | I14: 741 | M14: 9736.74 | N14: =M14*H14 -> 9736.74 | O14: =IF(I14>0.1,I14*2.20462," ") -> 1633.6234 | P14: =J14/2.54 -> 0 | Q14: =K14/2.54 -> 0 | R14: =L14/2.54 -> 0 | S14: =M14/18 -> 540.93 | T14: =S14*H14 -> 540.93
C15: ORANGE FOUNTAIN ROCK | D15: DH82539FDL | E15: FDL | F15: EDH | H15: 1 | I15: 690 | M15: 9066.6 | N15: =M15*H15 -> 9066.6 | O15: =IF(I15>0.1,I15*2.20462," ") -> 1521.1878 | P15: =J15/2.54 -> 0 | Q15: =K15/2.54 -> 0 | R15: =L15/2.54 -> 0 | S15: =M15/18 -> 503.7 | T15: =S15*H15 -> 503.7
C16: ORANGE FOUNTAIN ROCK | D16: DH82540AHD | E16: AHD | F16: LDD | H16: 1 | I16: 822 | M16: 10801.08 | N16: =M16*H16 -> 10801.08 | O16: =IF(I16>0.1,I16*2.20462," ") -> 1812.1976 | P16: =J16/2.54 -> 0 | Q16: =K16/2.54 -> 0 | R16: =L16/2.54 -> 0 | S16: =M16/18 -> 600.06 | T16: =S16*H16 -> 600.06
C17: ORANGE FOUNTAIN ROCK | D17: DH82541LML | E17: LML | F17: HHD | H17: 1 | I17: 603 | M17: 7923.42 | N17: =M17*H17 -> 7923.42 | O17: =IF(I17>0.1,I17*2.20462," ") -> 1329.3859 | P17: =J17/2.54 -> 0 | Q17: =K17/2.54 -> 0 | R17: =L17/2.54 -> 0 | S17: =M17/18 -> 440.19 | T17: =S17*H17 -> 440.19
C18: ZEBRA RUSTIC FOUNTAIN | D18: DH82542HFX | E18: HFX | F18: XXA | H18: 1 | I18: 463 | M18: 6083.82 | N18: =M18*H18 -> 6083.82 | O18: =IF(I18>0.1,I18*2.20462," ") -> 1020.7391 | P18: =J18/2.54 -> 0 | Q18: =K18/2.54 -> 0 | R18: =L18/2.54 -> 0 | S18: =M18/18 -> 337.99 | T18: =S18*H18 -> 337.99
C19: ZEBRA RUSTIC FOUNTAIN | D19: DH82543EHE | E19: EHE | F19: XAN | H19: 1 | I19: 533 | M19: 7003.62 | N19: =M19*H19 -> 7003.62 | O19: =IF(I19>0.1,I19*2.20462," ") -> 1175.0625 | P19: =J19/2.54 -> 0 | Q19: =K19/2.54 -> 0 | R19: =L19/2.54 -> 0 | S19: =M19/18 -> 389.09 | T19: =S19*H19 -> 389.09
... C26: GREEN TALAN RUSTIC ROCK | D26: TE82522HML | E26: HML | F26: ONF | H26: 1 | I26: 504 | M26: 5336 | N26: =M26*H26 -> 5336 | O26: =IF(I26>0.1,I26*2.20462," ") -> 1111.1285 | P26: =J26/2.54 -> 0 | Q26: =K26/2.54 -> 0 | R26: =L26/2.54 -> 0 | S26: =M26/18 -> 296.44444 | T26: =S26*H26 -> 296.44444
C27: PINK SER RUSTIC FTN | D27: BT82504HHM | E27: HHM | F27: XME | H27: 1 | I27: 473 | J27: 140 | K27: 55 | L27: 40 | M27: 5676 | N27: =M27*H27 -> 5676 | O27: =IF(I27>0.1,I27*2.20462," ") -> 1042.7853 | P27: =J27/2.54 -> 55.11811 | Q27: =K27/2.54 -> 21.653543 | R27: =L27/2.54 -> 15.748031 | S27: =M27/18 -> 315.33333 | T27: =S27*H27 -> 315.33333
C28: PINK SER RUSTIC FTN | D28: BT82505OAF | E28: OAF | F28: ODE | H28: 1 | I28: 308 | J28: 140 | K28: 48 | L28: 30 | M28: 3696 | N28: =M28*H28 -> 3696 | O28: =IF(I28>0.1,I28*2.20462," ") -> 679.02296 | P28: =J28/2.54 -> 55.11811 | Q28: =K28/2.54 -> 18.897638 | R28: =L28/2.54 -> 11.811024 | S28: =M28/18 -> 205.33333 | T28: =S28*H28 -> 205.33333
